Workbook
Name MonthTabs: সেটিংস!$I$2:$I$13

Sheet নির্দেশিকা
B2: দৈনিক খরচের হিসাব ২০২৬ — ব্যবহার নির্দেশিকা
B4: এই ফাইলে কী আছে | C4: ১৮টি শিট: এই নির্দেশিকা, একটি বার্ষিক সারসংক্ষেপ, তিনটি লেজার শিট (ধার-দেনা, বাজেট, পুনরাবৃত্ত খরচ), ১২টি মাসিক শিট (জানুয়ারি–ডিসেম্বর ২০২৬) এবং একটি সেটিংস শিট।
B5: কোথায় লিখবেন | C5: মাসিক শিটের A থেকে G কলামে (৪–২০৩ সারি), এবং তিনটি লেজার শিটে। ধূসর ও ইটালিক ঘরগুলো সূত্র — সেখানে কিছু লিখবেন না।
B6: তারিখ (কলাম A) | C6: DD/MM/YYYY আকারে লিখুন, যেমন ০৫/০১/২০২৬। মাসের বাইরের তারিখ দিলে সতর্কবার্তা আসবে — চাইলে রেখে দেওয়া যাবে।
B7: বিবরণ (কলাম B) | C7: খরচের সংক্ষিপ্ত বর্ণনা, যেমন ‘৫ কেজি মিনিকেট চাল’।
B8: খাত (কলাম C) | C8: ড্রপ-ডাউন থেকে নির্বাচন করুন। মোট ৫৪টি খাত ৮টি গ্রুপে সাজানো — চাল, ডাল, মাছ, বাড়ি ভাড়া, বিদ্যুৎ বিল ইত্যাদি। তালিকার বাইরের খাত লেখা যাবে না; নতুন খাত দরকার হলে ‘সেটিংস’ শিটে যোগ করুন।
B9: গ্রুপ (কলাম D) | C9: স্বয়ংক্রিয়ভাবে পূরণ হয় — এখানে কিছু লিখবেন না।
B10: পরিমাণ (কলাম E) | C10: শুধু সংখ্যা লিখুন, টাকার চিহ্ন নিজে থেকে বসবে। ঋণাত্মক সংখ্যা গ্রহণযোগ্য নয়।
B11: পেমেন্ট মাধ্যম (কলাম F) | C11: ড্রপ-ডাউন — নগদ টাকা, বিকাশ, নগদ (অ্যাপ), রকেট, কার্ড, ব্যাংক ট্রান্সফার।
B12: মন্তব্য (কলাম G) | C12: ঐচ্ছিক — দোকানের নাম, রসিদ নম্বর ইত্যাদি।
B13: মাসিক সারসংক্ষেপ | C13: প্রতিটি মাসিক শিটের ডান পাশে (I–K কলাম) গ্রুপভিত্তিক মোট, শতাংশ, দৈনিক গড় ও খাতভিত্তিক বিস্তারিত হিসাব স্বয়ংক্রিয়ভাবে দেখা যাবে।
B14: বার্ষিক সারসংক্ষেপ | C14: ‘বার্ষিক সারসংক্ষেপ’ শিটে ১২ মাসের সব হিসাব একসাথে, দুটি চার্টসহ। এই শিটে হাতে কিছু লেখার দরকার নেই।
B15: নতুন খাত যোগ করা | C15: ‘সেটিংস’ শিটের B ও C কলামের তালিকার শেষে নতুন খাত ও তার গ্রুপ যোগ করুন, তারপর Formulas → Name Manager থেকে CategoryList ও GroupLookup নামের সীমা বাড়িয়ে দিন।
... B26: অ্যাপ থেকে সিঙ্ক | C26: ‘পই পই হিসাব’ অ্যাপের সেটিংস থেকে সিঙ্ক করলে মাসিক শিটের খরচ এবং এই তিনটি লেজার শিট — তিনটিই সম্পূর্ণ নতুন করে লেখা হয়। একই সিঙ্ক বারবার করলে কিছু দ্বিগুণ হয় না। শিটে হাতে করা বদল পরের সিঙ্কে মুছে যাবে, তাই অ্যাপ চালু থাকলে বদলগুলো অ্যাপে করুন।

Sheet বার্ষিক সারসংক্ষেপ
A1: বার্ষিক খরচের সারসংক্ষেপ — ২০২৬
A2: সব সংখ্যা মাসিক শিটগুলো থেকে স্বয়ংক্রিয়ভাবে আসে। এই শিটে কোনো কিছু হাতে লিখতে হবে না।
A4: বার্ষিক মোট ব্যয় | D4: মাসিক গড় ব্যয় | G4: সর্বোচ্চ ব্যয়ের মাস | J4: সর্বোচ্চ ব্যয়ের গ্রুপ
A5: =SUM($B$18:$M$18) | D5: =IFERROR(AVERAGE($B$18:$M$18),0) | G5: {=IF(SUM($B$18:$M$18)=0,"–",IFERROR(INDEX($B$8:$M$8,MATCH(MAX($B$18:$M$18),$B$18:$M$18,0)),"–"))} | J5: {=IF($N$18=0,"–",IFERROR(INDEX($A$10:$A$17,MATCH(MAX($N$10:$N$17),$N$10:$N$17,0)),"–"))}
A7: গ্রুপভিত্তিক মাসিক ব্যয়
A8: গ্রুপ / মাস | B8: জানুয়ারি | C8: ফেব্রুয়ারি | D8: মার্চ | E8: এপ্রিল | F8: মে | G8: জুন | H8: জুলাই | I8: আগস্ট | J8: সেপ্টেম্বর | K8: অক্টোবর | L8: নভেম্বর | M8: ডিসেম্বর | N8: বার্ষিক মোট
A10: খাদ্য ও মুদি | B10: ='জানুয়ারি ২০২৬'!$J$4 | C10: ='ফেব্রুয়ারি ২০২৬'!$J$4 | D10: ='মার্চ ২০২৬'!$J$4 | E10: ='এপ্রিল ২০২৬'!$J$4 | F10: ='মে ২০২৬'!$J$4 | G10: ='জুন ২০২৬'!$J$4 | H10: ='জুলাই ২০২৬'!$J$4 | I10: ='আগস্ট ২০২৬'!$J$4 | J10: ='সেপ্টেম্বর ২০২৬'!$J$4 | K10: ='অক্টোবর ২০২৬'!$J$4 | L10: ='নভেম্বর ২০২৬'!$J$4 | M10: ='ডিসেম্বর ২০২৬'!$J$4 | N10: =SUM($B10:$M10)
A11: বাসস্থান | B11: ='জানুয়ারি ২০২৬'!$J$5 | C11: ='ফেব্রুয়ারি ২০২৬'!$J$5 | D11: ='মার্চ ২০২৬'!$J$5 | E11: ='এপ্রিল ২০২৬'!$J$5 | F11: ='মে ২০২৬'!$J$5 | G11: ='জুন ২০২৬'!$J$5 | H11: ='জুলাই ২০২৬'!$J$5 | I11: ='আগস্ট ২০২৬'!$J$5 | J11: ='সেপ্টেম্বর ২০২৬'!$J$5 | K11: ='অক্টোবর ২০২৬'!$J$5 | L11: ='নভেম্বর ২০২৬'!$J$5 | M11: ='ডিসেম্বর ২০২৬'!$J$5 | N11: =SUM($B11:$M11)
A12: ইউটিলিটি বিল | B12: ='জানুয়ারি ২০২৬'!$J$6 | C12: ='ফেব্রুয়ারি ২০২৬'!$J$6 | D12: ='মার্চ ২০২৬'!$J$6 | E12: ='এপ্রিল ২০২৬'!$J$6 | F12: ='মে ২০২৬'!$J$6 | G12: ='জুন ২০২৬'!$J$6 | H12: ='জুলাই ২০২৬'!$J$6 | I12: ='আগস্ট ২০২৬'!$J$6 | J12: ='সেপ্টেম্বর ২০২৬'!$J$6 | K12: ='অক্টোবর ২০২৬'!$J$6 | L12: ='নভেম্বর ২০২৬'!$J$6 | M12: ='ডিসেম্বর ২০২৬'!$J$6 | N12: =SUM($B12:$M12)
A13: যাতায়াত | B13: ='জানুয়ারি ২০২৬'!$J$7 | C13: ='ফেব্রুয়ারি ২০২৬'!$J$7 | D13: ='মার্চ ২০২৬'!$J$7 | E13: ='এপ্রিল ২০২৬'!$J$7 | F13: ='মে ২০২৬'!$J$7 | G13: ='জুন ২০২৬'!$J$7 | H13: ='জুলাই ২০২৬'!$J$7 | I13: ='আগস্ট ২০২৬'!$J$7 | J13: ='সেপ্টেম্বর ২০২৬'!$J$7 | K13: ='অক্টোবর ২০২৬'!$J$7 | L13: ='নভেম্বর ২০২৬'!$J$7 | M13: ='ডিসেম্বর ২০২৬'!$J$7 | N13: =SUM($B13:$M13)
A14: স্বাস্থ্য | B14: ='জানুয়ারি ২০২৬'!$J$8 | C14: ='ফেব্রুয়ারি ২০২৬'!$J$8 | D14: ='মার্চ ২০২৬'!$J$8 | E14: ='এপ্রিল ২০২৬'!$J$8 | F14: ='মে ২০২৬'!$J$8 | G14: ='জুন ২০২৬'!$J$8 | H14: ='জুলাই ২০২৬'!$J$8 | I14: ='আগস্ট ২০২৬'!$J$8 | J14: ='সেপ্টেম্বর ২০২৬'!$J$8 | K14: ='অক্টোবর ২০২৬'!$J$8 | L14: ='নভেম্বর ২০২৬'!$J$8 | M14: ='ডিসেম্বর ২০২৬'!$J$8 | N14: =SUM($B14:$M14)
A15: শিক্ষা | B15: ='জানুয়ারি ২০২৬'!$J$9 | C15: ='ফেব্রুয়ারি ২০২৬'!$J$9 | D15: ='মার্চ ২০২৬'!$J$9 | E15: ='এপ্রিল ২০২৬'!$J$9 | F15: ='মে ২০২৬'!$J$9 | G15: ='জুন ২০২৬'!$J$9 | H15: ='জুলাই ২০২৬'!$J$9 | I15: ='আগস্ট ২০২৬'!$J$9 | J15: ='সেপ্টেম্বর ২০২৬'!$J$9 | K15: ='অক্টোবর ২০২৬'!$J$9 | L15: ='নভেম্বর ২০২৬'!$J$9 | M15: ='ডিসেম্বর ২০২৬'!$J$9 | N15: =SUM($B15:$M15)
A16: ব্যক্তিগত ও গৃহস্থালি | B16: ='জানুয়ারি ২০২৬'!$J$10 | C16: ='ফেব্রুয়ারি ২০২৬'!$J$10 | D16: ='মার্চ ২০২৬'!$J$10 | E16: ='এপ্রিল ২০২৬'!$J$10 | F16: ='মে ২০২৬'!$J$10 | G16: ='জুন ২০২৬'!$J$10 | H16: ='জুলাই ২০২৬'!$J$10 | I16: ='আগস্ট ২০২৬'!$J$10 | J16: ='সেপ্টেম্বর ২০২৬'!$J$10 | K16: ='অক্টোবর ২০২৬'!$J$10 | L16: ='নভেম্বর ২০২৬'!$J$10 | M16: ='ডিসেম্বর ২০২৬'!$J$10 | N16: =SUM($B16:$M16)
A17: অন্যান্য | B17: ='জানুয়ারি ২০২৬'!$J$11 | C17: ='ফেব্রুয়ারি ২০২৬'!$J$11 | D17: ='মার্চ ২০২৬'!$J$11 | E17: ='এপ্রিল ২০২৬'!$J$11 | F17: ='মে ২০২৬'!$J$11 | G17: ='জুন ২০২৬'!$J$11 | H17: ='জুলাই ২০২৬'!$J$11 | I17: ='আগস্ট ২০২৬'!$J$11 | J17: ='সেপ্টেম্বর ২০২৬'!$J$11 | K17: ='অক্টোবর ২০২৬'!$J$11 | L17: ='নভেম্বর ২০২৬'!$J$11 | M17: ='ডিসেম্বর ২০২৬'!$J$11 | N17: =SUM($B17:$M17)
A18: মাসিক মোট | B18: ='জানুয়ারি ২০২৬'!$J$12 | C18: ='ফেব্রুয়ারি ২০২৬'!$J$12 | D18: ='মার্চ ২০২৬'!$J$12 | E18: ='এপ্রিল ২০২৬'!$J$12 | F18: ='মে ২০২৬'!$J$12 | G18: ='জুন ২০২৬'!$J$12 | H18: ='জুলাই ২০২৬'!$J$12 | I18: ='আগস্ট ২০২৬'!$J$12 | J18: ='সেপ্টেম্বর ২০২৬'!$J$12 | K18: ='অক্টোবর ২০২৬'!$J$12 | L18: ='নভেম্বর ২০২৬'!$J$12 | M18: ='ডিসেম্বর ২০২৬'!$J$12 | N18: =SUM($B$18:$M$18)
A19: শ্রেণিবিন্যাসহীন | B19: ='জানুয়ারি ২০২৬'!$J$13 | C19: ='ফেব্রুয়ারি ২০২৬'!$J$13 | D19: ='মার্চ ২০২৬'!$J$13 | E19: ='এপ্রিল ২০২৬'!$J$13 | F19: ='মে ২০২৬'!$J$13 | G19: ='জুন ২০২৬'!$J$13 | H19: ='জুলাই ২০২৬'!$J$13 | I19: ='আগস্ট ২০২৬'!$J$13 | J19: ='সেপ্টেম্বর ২০২৬'!$J$13 | K19: ='অক্টোবর ২০২৬'!$J$13 | L19: ='নভেম্বর ২০২৬'!$J$13 | M19: ='ডিসেম্বর ২০২৬'!$J$13 | N19: =SUM($B$19:$M$19)
A40: খাতভিত্তিক মাসিক ব্যয় (বিস্তারিত)
A41: খাত / মাস | B41: জানুয়ারি | C41: ফেব্রুয়ারি | D41: মার্চ | E41: এপ্রিল | F41: মে | G41: জুন | H41: জুলাই | I41: আগস্ট | J41: সেপ্টেম্বর | K41: অক্টোবর | L41: নভেম্বর | M41: ডিসেম্বর | N41: বার্ষিক মোট
A42: চাল | B42: ='জানুয়ারি ২০২৬'!$J$23 | C42: ='ফেব্রুয়ারি ২০২৬'!$J$23 | D42: ='মার্চ ২০২৬'!$J$23 | E42: ='এপ্রিল ২০২৬'!$J$23 | F42: ='মে ২০২৬'!$J$23 | G42: ='জুন ২০২৬'!$J$23 | H42: ='জুলাই ২০২৬'!$J$23 | I42: ='আগস্ট ২০২৬'!$J$23 | J42: ='সেপ্টেম্বর ২০২৬'!$J$23 | K42: ='অক্টোবর ২০২৬'!$J$23 | L42: ='নভেম্বর ২০২৬'!$J$23 | M42: ='ডিসেম্বর ২০২৬'!$J$23 | N42: =SUM($B42:$M42)
A43: আটা ও ময়দা | B43: ='জানুয়ারি ২০২৬'!$J$24 | C43: ='ফেব্রুয়ারি ২০২৬'!$J$24 | D43: ='মার্চ ২০২৬'!$J$24 | E43: ='এপ্রিল ২০২৬'!$J$24 | F43: ='মে ২০২৬'!$J$24 | G43: ='জুন ২০২৬'!$J$24 | H43: ='জুলাই ২০২৬'!$J$24 | I43: ='আগস্ট ২০২৬'!$J$24 | J43: ='সেপ্টেম্বর ২০২৬'!$J$24 | K43: ='অক্টোবর ২০২৬'!$J$24 | L43: ='নভেম্বর ২০২৬'!$J$24 | M43: ='ডিসেম্বর ২০২৬'!$J$24 | N43: =SUM($B43:$M43)
A44: ডাল | B44: ='জানুয়ারি ২০২৬'!$J$25 | C44: ='ফেব্রুয়ারি ২০২৬'!$J$25 | D44: ='মার্চ ২০২৬'!$J$25 | E44: ='এপ্রিল ২০২৬'!$J$25 | F44: ='মে ২০২৬'!$J$25 | G44: ='জুন ২০২৬'!$J$25 | H44: ='জুলাই ২০২৬'!$J$25 | I44: ='আগস্ট ২০২৬'!$J$25 | J44: ='সেপ্টেম্বর ২০২৬'!$J$25 | K44: ='অক্টোবর ২০২৬'!$J$25 | L44: ='নভেম্বর ২০২৬'!$J$25 | M44: ='ডিসেম্বর ২০২৬'!$J$25 | N44: =SUM($B44:$M44)
A45: মাছ | B45: ='জানুয়ারি ২০২৬'!$J$26 | C45: ='ফেব্রুয়ারি ২০২৬'!$J$26 | D45: ='মার্চ ২০২৬'!$J$26 | E45: ='এপ্রিল ২০২৬'!$J$26 | F45: ='মে ২০২৬'!$J$26 | G45: ='জুন ২০২৬'!$J$26 | H45: ='জুলাই ২০২৬'!$J$26 | I45: ='আগস্ট ২০২৬'!$J$26 | J45: ='সেপ্টেম্বর ২০২৬'!$J$26 | K45: ='অক্টোবর ২০২৬'!$J$26 | L45: ='নভেম্বর ২০২৬'!$J$26 | M45: ='ডিসেম্বর ২০২৬'!$J$26 | N45: =SUM($B45:$M45)
A46: মাংস | B46: ='জানুয়ারি ২০২৬'!$J$27 | C46: ='ফেব্রুয়ারি ২০২৬'!$J$27 | D46: ='মার্চ ২০২৬'!$J$27 | E46: ='এপ্রিল ২০২৬'!$J$27 | F46: ='মে ২০২৬'!$J$27 | G46: ='জুন ২০২৬'!$J$27 | H46: ='জুলাই ২০২৬'!$J$27 | I46: ='আগস্ট ২০২৬'!$J$27 | J46: ='সেপ্টেম্বর ২০২৬'!$J$27 | K46: ='অক্টোবর ২০২৬'!$J$27 | L46: ='নভেম্বর ২০২৬'!$J$27 | M46: ='ডিসেম্বর ২০২৬'!$J$27 | N46: =SUM($B46:$M46)
A47: ডিম | B47: ='জানুয়ারি ২০২৬'!$J$28 | C47: ='ফেব্রুয়ারি ২০২৬'!$J$28 | D47: ='মার্চ ২০২৬'!$J$28 | E47: ='এপ্রিল ২০২৬'!$J$28 | F47: ='মে ২০২৬'!$J$28 | G47: ='জুন ২০২৬'!$J$28 | H47: ='জুলাই ২০২৬'!$J$28 | I47: ='আগস্ট ২০২৬'!$J$28 | J47: ='সেপ্টেম্বর ২০২৬'!$J$28 | K47: ='অক্টোবর ২০২৬'!$J$28 | L47: ='নভেম্বর ২০২৬'!$J$28 | M47: ='ডিসেম্বর ২০২৬'!$J$28 | N47: =SUM($B47:$M47)
A48: দুধ ও দুগ্ধজাত পণ্য | B48: ='জানুয়ারি ২০২৬'!$J$29 | C48: ='ফেব্রুয়ারি ২০২৬'!$J$29 | D48: ='মার্চ ২০২৬'!$J$29 | E48: ='এপ্রিল ২০২৬'!$J$29 | F48: ='মে ২০২৬'!$J$29 | G48: ='জুন ২০২৬'!$J$29 | H48: ='জুলাই ২০২৬'!$J$29 | I48: ='আগস্ট ২০২৬'!$J$29 | J48: ='সেপ্টেম্বর ২০২৬'!$J$29 | K48: ='অক্টোবর ২০২৬'!$J$29 | L48: ='নভেম্বর ২০২৬'!$J$29 | M48: ='ডিসেম্বর ২০২৬'!$J$29 | N48: =SUM($B48:$M48)
A49: ভোজ্য তেল | B49: ='জানুয়ারি ২০২৬'!$J$30 | C49: ='ফেব্রুয়ারি ২০২৬'!$J$30 | D49: ='মার্চ ২০২৬'!$J$30 | E49: ='এপ্রিল ২০২৬'!$J$30 | F49: ='মে ২০২৬'!$J$30 | G49: ='জুন ২০২৬'!$J$30 | H49: ='জুলাই ২০২৬'!$J$30 | I49: ='আগস্ট ২০২৬'!$J$30 | J49: ='সেপ্টেম্বর ২০২৬'!$J$30 | K49: ='অক্টোবর ২০২৬'!$J$30 | L49: ='নভেম্বর ২০২৬'!$J$30 | M49: ='ডিসেম্বর ২০২৬'!$J$30 | N49: =SUM($B49:$M49)
A50: শাক-সবজি | B50: ='জানুয়ারি ২০২৬'!$J$31 | C50: ='ফেব্রুয়ারি ২০২৬'!$J$31 | D50: ='মার্চ ২০২৬'!$J$31 | E50: ='এপ্রিল ২০২৬'!$J$31 | F50: ='মে ২০২৬'!$J$31 | G50: ='জুন ২০২৬'!$J$31 | H50: ='জুলাই ২০২৬'!$J$31 | I50: ='আগস্ট ২০২৬'!$J$31 | J50: ='সেপ্টেম্বর ২০২৬'!$J$31 | K50: ='অক্টোবর ২০২৬'!$J$31 | L50: ='নভেম্বর ২০২৬'!$J$31 | M50: ='ডিসেম্বর ২০২৬'!$J$31 | N50: =SUM($B50:$M50)
A51: ফলমূল | B51: ='জানুয়ারি ২০২৬'!$J$32 | C51: ='ফেব্রুয়ারি ২০২৬'!$J$32 | D51: ='মার্চ ২০২৬'!$J$32 | E51: ='এপ্রিল ২০২৬'!$J$32 | F51: ='মে ২০২৬'!$J$32 | G51: ='জুন ২০২৬'!$J$32 | H51: ='জুলাই ২০২৬'!$J$32 | I51: ='আগস্ট ২০২৬'!$J$32 | J51: ='সেপ্টেম্বর ২০২৬'!$J$32 | K51: ='অক্টোবর ২০২৬'!$J$32 | L51: ='নভেম্বর ২০২৬'!$J$32 | M51: ='ডিসেম্বর ২০২৬'!$J$32 | N51: =SUM($B51:$M51)
A52: মসলা | B52: ='জানুয়ারি ২০২৬'!$J$33 | C52: ='ফেব্রুয়ারি ২০২৬'!$J$33 | D52: ='মার্চ ২০২৬'!$J$33 | E52: ='এপ্রিল ২০২৬'!$J$33 | F52: ='মে ২০২৬'!$J$33 | G52: ='জুন ২০২৬'!$J$33 | H52: ='জুলাই ২০২৬'!$J$33 | I52: ='আগস্ট ২০২৬'!$J$33 | J52: ='সেপ্টেম্বর ২০২৬'!$J$33 | K52: ='অক্টোবর ২০২৬'!$J$33 | L52: ='নভেম্বর ২০২৬'!$J$33 | M52: ='ডিসেম্বর ২০২৬'!$J$33 | N52: =SUM($B52:$M52)
A53: চিনি ও লবণ | B53: ='জানুয়ারি ২০২৬'!$J$34 | C53: ='ফেব্রুয়ারি ২০২৬'!$J$34 | D53: ='মার্চ ২০২৬'!$J$34 | E53: ='এপ্রিল ২০২৬'!$J$34 | F53: ='মে ২০২৬'!$J$34 | G53: ='জুন ২০২৬'!$J$34 | H53: ='জুলাই ২০২৬'!$J$34 | I53: ='আগস্ট ২০২৬'!$J$34 | J53: ='সেপ্টেম্বর ২০২৬'!$J$34 | K53: ='অক্টোবর ২০২৬'!$J$34 | L53: ='নভেম্বর ২০২৬'!$J$34 | M53: ='ডিসেম্বর ২০২৬'!$J$34 | N53: =SUM($B53:$M53)
A54: চা ও কফি | B54: ='জানুয়ারি ২০২৬'!$J$35 | C54: ='ফেব্রুয়ারি ২০২৬'!$J$35 | D54: ='মার্চ ২০২৬'!$J$35 | E54: ='এপ্রিল ২০২৬'!$J$35 | F54: ='মে ২০২৬'!$J$35 | G54: ='জুন ২০২৬'!$J$35 | H54: ='জুলাই ২০২৬'!$J$35 | I54: ='আগস্ট ২০২৬'!$J$35 | J54: ='সেপ্টেম্বর ২০২৬'!$J$35 | K54: ='অক্টোবর ২০২৬'!$J$35 | L54: ='নভেম্বর ২০২৬'!$J$35 | M54: ='ডিসেম্বর ২০২৬'!$J$35 | N54: =SUM($B54:$M54)
A55: নাশতা ও বেকারি | B55: ='জানুয়ারি ২০২৬'!$J$36 | C55: ='ফেব্রুয়ারি ২০২৬'!$J$36 | D55: ='মার্চ ২০২৬'!$J$36 | E55: ='এপ্রিল ২০২৬'!$J$36 | F55: ='মে ২০২৬'!$J$36 | G55: ='জুন ২০২৬'!$J$36 | H55: ='জুলাই ২০২৬'!$J$36 | I55: ='আগস্ট ২০২৬'!$J$36 | J55: ='সেপ্টেম্বর ২০২৬'!$J$36 | K55: ='অক্টোবর ২০২৬'!$J$36 | L55: ='নভেম্বর ২০২৬'!$J$36 | M55: ='ডিসেম্বর ২০২৬'!$J$36 | N55: =SUM($B55:$M55)
A56: বাইরে খাওয়া / রেস্তোরাঁ | B56: ='জানুয়ারি ২০২৬'!$J$37 | C56: ='ফেব্রুয়ারি ২০২৬'!$J$37 | D56: ='মার্চ ২০২৬'!$J$37 | E56: ='এপ্রিল ২০২৬'!$J$37 | F56: ='মে ২০২৬'!$J$37 | G56: ='জুন ২০২৬'!$J$37 | H56: ='জুলাই ২০২৬'!$J$37 | I56: ='আগস্ট ২০২৬'!$J$37 | J56: ='সেপ্টেম্বর ২০২৬'!$J$37 | K56: ='অক্টোবর ২০২৬'!$J$37 | L56: ='নভেম্বর ২০২৬'!$J$37 | M56: ='ডিসেম্বর ২০২৬'!$J$37 | N56: =SUM($B56:$M56)
A57: বাড়ি ভাড়া | B57: ='জানুয়ারি ২০২৬'!$J$38 | C57: ='ফেব্রুয়ারি ২০২৬'!$J$38 | D57: ='মার্চ ২০২৬'!$J$38 | E57: ='এপ্রিল ২০২৬'!$J$38 | F57: ='মে ২০২৬'!$J$38 | G57: ='জুন ২০২৬'!$J$38 | H57: ='জুলাই ২০২৬'!$J$38 | I57: ='আগস্ট ২০২৬'!$J$38 | J57: ='সেপ্টেম্বর ২০২৬'!$J$38 | K57: ='অক্টোবর ২০২৬'!$J$38 | L57: ='নভেম্বর ২০২৬'!$J$38 | M57: ='ডিসেম্বর ২০২৬'!$J$38 | N57: =SUM($B57:$M57)
A58: সার্ভিস চার্জ | B58: ='জানুয়ারি ২০২৬'!$J$39 | C58: ='ফেব্রুয়ারি ২০২৬'!$J$39 | D58: ='মার্চ ২০২৬'!$J$39 | E58: ='এপ্রিল ২০২৬'!$J$39 | F58: ='মে ২০২৬'!$J$39 | G58: ='জুন ২০২৬'!$J$39 | H58: ='জুলাই ২০২৬'!$J$39 | I58: ='আগস্ট ২০২৬'!$J$39 | J58: ='সেপ্টেম্বর ২০২৬'!$J$39 | K58: ='অক্টোবর ২০২৬'!$J$39 | L58: ='নভেম্বর ২০২৬'!$J$39 | M58: ='ডিসেম্বর ২০২৬'!$J$39 | N58: =SUM($B58:$M58)
A59: বাড়ি মেরামত ও রক্ষণাবেক্ষণ | B59: ='জানুয়ারি ২০২৬'!$J$40 | C59: ='ফেব্রুয়ারি ২০২৬'!$J$40 | D59: ='মার্চ ২০২৬'!$J$40 | E59: ='এপ্রিল ২০২৬'!$J$40 | F59: ='মে ২০২৬'!$J$40 | G59: ='জুন ২০২৬'!$J$40 | H59: ='জুলাই ২০২৬'!$J$40 | I59: ='আগস্ট ২০২৬'!$J$40 | J59: ='সেপ্টেম্বর ২০২৬'!$J$40 | K59: ='অক্টোবর ২০২৬'!$J$40 | L59: ='নভেম্বর ২০২৬'!$J$40 | M59: ='ডিসেম্বর ২০২৬'!$J$40 | N59: =SUM($B59:$M59)
A60: গৃহকর্মীর বেতন | B60: ='জানুয়ারি ২০২৬'!$J$41 | C60: ='ফেব্রুয়ারি ২০২৬'!$J$41 | D60: ='মার্চ ২০২৬'!$J$41 | E60: ='এপ্রিল ২০২৬'!$J$41 | F60: ='মে ২০২৬'!$J$41 | G60: ='জুন ২০২৬'!$J$41 | H60: ='জুলাই ২০২৬'!$J$41 | I60: ='আগস্ট ২০২৬'!$J$41 | J60: ='সেপ্টেম্বর ২০২৬'!$J$41 | K60: ='অক্টোবর ২০২৬'!$J$41 | L60: ='নভেম্বর ২০২৬'!$J$41 | M60: ='ডিসেম্বর ২০২৬'!$J$41 | N60: =SUM($B60:$M60)
A61: আসবাবপত্র | B61: ='জানুয়ারি ২০২৬'!$J$42 | C61: ='ফেব্রুয়ারি ২০২৬'!$J$42 | D61: ='মার্চ ২০২৬'!$J$42 | E61: ='এপ্রিল ২০২৬'!$J$42 | F61: ='মে ২০২৬'!$J$42 | G61: ='জুন ২০২৬'!$J$42 | H61: ='জুলাই ২০২৬'!$J$42 | I61: ='আগস্ট ২০২৬'!$J$42 | J61: ='সেপ্টেম্বর ২০২৬'!$J$42 | K61: ='অক্টোবর ২০২৬'!$J$42 | L61: ='নভেম্বর ২০২৬'!$J$42 | M61: ='ডিসেম্বর ২০২৬'!$J$42 | N61: =SUM($B61:$M61)
A62: বিদ্যুৎ বিল | B62: ='জানুয়ারি ২০২৬'!$J$43 | C62: ='ফেব্রুয়ারি ২০২৬'!$J$43 | D62: ='মার্চ ২০২৬'!$J$43 | E62: ='এপ্রিল ২০২৬'!$J$43 | F62: ='মে ২০২৬'!$J$43 | G62: ='জুন ২০২৬'!$J$43 | H62: ='জুলাই ২০২৬'!$J$43 | I62: ='আগস্ট ২০২৬'!$J$43 | J62: ='সেপ্টেম্বর ২০২৬'!$J$43 | K62: ='অক্টোবর ২০২৬'!$J$43 | L62: ='নভেম্বর ২০২৬'!$J$43 | M62: ='ডিসেম্বর ২০২৬'!$J$43 | N62: =SUM($B62:$M62)
A63: গ্যাস বিল | B63: ='জানুয়ারি ২০২৬'!$J$44 | C63: ='ফেব্রুয়ারি ২০২৬'!$J$44 | D63: ='মার্চ ২০২৬'!$J$44 | E63: ='এপ্রিল ২০২৬'!$J$44 | F63: ='মে ২০২৬'!$J$44 | G63: ='জুন ২০২৬'!$J$44 | H63: ='জুলাই ২০২৬'!$J$44 | I63: ='আগস্ট ২০২৬'!$J$44 | J63: ='সেপ্টেম্বর ২০২৬'!$J$44 | K63: ='অক্টোবর ২০২৬'!$J$44 | L63: ='নভেম্বর ২০২৬'!$J$44 | M63: ='ডিসেম্বর ২০২৬'!$J$44 | N63: =SUM($B63:$M63)
...

Sheet ধার-দেনা
A1: ধার-দেনা — কে কত পাবে / দেবে | I1: সারসংক্ষেপ
A2: অ্যাপ থেকে সিঙ্ক করলে এই শিটের ৪–১০৩ সারি সম্পূর্ণ নতুন করে লেখা হয়। ‘অবস্থা’ কলাম স্বয়ংক্রিয় — এখানে কিছু লিখবেন না। ‘বাকি’ মানে এখনো অপরিশোধিত অংশ, মূল ধারের পরিমাণ নয়।
A3: তারিখ | B3: কার সাথে | C3: ধরন | D3: বাকি (৳) | E3: নোট | F3: অবস্থা | G3: পরিশোধের তারিখ | I3: হিসাব | J3: মোট (৳)
F4: =IF($A4="","",IF($G4="","চলমান","পরিশোধিত")) | I4: মোট পাবো (ধার দিয়েছি) — চলমান | J4: =SUMIFS($D$4:$D$103,$C$4:$C$103,"ধার দিয়েছি",$G$4:$G$103,"")
F5: =IF($A5="","",IF($G5="","চলমান","পরিশোধিত")) | I5: মোট দেবো (ধার নিয়েছি) — চলমান | J5: =SUMIFS($D$4:$D$103,$C$4:$C$103,"ধার নিয়েছি",$G$4:$G$103,"")
F6: =IF($A6="","",IF($G6="","চলমান","পরিশোধিত")) | I6: নিট অবস্থান (পাবো − দেবো) | J6: =$J$4-$J$5
F7: =IF($A7="","",IF($G7="","চলমান","পরিশোধিত")) | I7: পরিশোধিত (মোট) | J7: =SUMIFS($D$4:$D$103,$G$4:$G$103,"<>")
F8: =IF($A8="","",IF($G8="","চলমান","পরিশোধিত")) | I8: চলমান এন্ট্রি | J8: =COUNTIFS($A$4:$A$103,"<>",$G$4:$G$103,"")
F9: =IF($A9="","",IF($G9="","চলমান","পরিশোধিত")) | I9: মোট এন্ট্রি | J9: =COUNTIF($A$4:$A$103,"<>")
F10: =IF($A10="","",IF($G10="","চলমান","পরিশোধিত"))
F11: =IF($A11="","",IF($G11="","চলমান","পরিশোধিত"))
F12: =IF($A12="","",IF($G12="","চলমান","পরিশোধিত"))
F13: =IF($A13="","",IF($G13="","চলমান","পরিশোধিত"))
F14: =IF($A14="","",IF($G14="","চলমান","পরিশোধিত"))
F15: =IF($A15="","",IF($G15="","চলমান","পরিশোধিত"))
F16: =IF($A16="","",IF($G16="","চলমান","পরিশোধিত"))
F17: =IF($A17="","",IF($G17="","চলমান","পরিশোধিত"))
F18: =IF($A18="","",IF($G18="","চলমান","পরিশোধিত"))
F19: =IF($A19="","",IF($G19="","চলমান","পরিশোধিত"))
F20: =IF($A20="","",IF($G20="","চলমান","পরিশোধিত"))
F21: =IF($A21="","",IF($G21="","চলমান","পরিশোধিত"))
... F103: =IF($A103="","",IF($G103="","চলমান","পরিশোধিত"))

Sheet বাজেট
A1: বাজেট — খরচ বনাম সীমা
A2: মাস | B2: জানুয়ারি ২০২৬ | C2: মোট মাসিক বাজেট (৳) | E2: =IF($D$2=0,"",IF(SUM($B$4:$B$53)>$D$2,"⚠ খাতভিত্তিক সীমার যোগফল মোট বাজেটের বেশি",""))
A3: খাত | B3: মাসিক সীমা (৳) | C3: এই মাসের খরচ (৳) | D3: বাকি (৳) | E3: ব্যবহার | F3: অবস্থা
C4: =IF($A4="","",SUMIF(INDIRECT("'"&$B$2&"'!$C$4:$C$203"),$A4,INDIRECT("'"&$B$2&"'!$E$4:$E$203"))) | D4: =IF($A4="","",$B4-$C4) | E4: =IF($A4="","",IFERROR($C4/$B4,0)) | F4: =IF($A4="","",IF($B4=0,"—",IF($E4>1,"বেশি হয়ে গেছে",IF($E4>=0.8,"সতর্ক","ভালো"))))
C5: =IF($A5="","",SUMIF(INDIRECT("'"&$B$2&"'!$C$4:$C$203"),$A5,INDIRECT("'"&$B$2&"'!$E$4:$E$203"))) | D5: =IF($A5="","",$B5-$C5) | E5: =IF($A5="","",IFERROR($C5/$B5,0)) | F5: =IF($A5="","",IF($B5=0,"—",IF($E5>1,"বেশি হয়ে গেছে",IF($E5>=0.8,"সতর্ক","ভালো"))))
C6: =IF($A6="","",SUMIF(INDIRECT("'"&$B$2&"'!$C$4:$C$203"),$A6,INDIRECT("'"&$B$2&"'!$E$4:$E$203"))) | D6: =IF($A6="","",$B6-$C6) | E6: =IF($A6="","",IFERROR($C6/$B6,0)) | F6: =IF($A6="","",IF($B6=0,"—",IF($E6>1,"বেশি হয়ে গেছে",IF($E6>=0.8,"সতর্ক","ভালো"))))
C7: =IF($A7="","",SUMIF(INDIRECT("'"&$B$2&"'!$C$4:$C$203"),$A7,INDIRECT("'"&$B$2&"'!$E$4:$E$203"))) | D7: =IF($A7="","",$B7-$C7) | E7: =IF($A7="","",IFERROR($C7/$B7,0)) | F7: =IF($A7="","",IF($B7=0,"—",IF($E7>1,"বেশি হয়ে গেছে",IF($E7>=0.8,"সতর্ক","ভালো"))))
C8: =IF($A8="","",SUMIF(INDIRECT("'"&$B$2&"'!$C$4:$C$203"),$A8,INDIRECT("'"&$B$2&"'!$E$4:$E$203"))) | D8: =IF($A8="","",$B8-$C8) | E8: =IF($A8="","",IFERROR($C8/$B8,0)) | F8: =IF($A8="","",IF($B8=0,"—",IF($E8>1,"বেশি হয়ে গেছে",IF($E8>=0.8,"সতর্ক","ভালো"))))
C9: =IF($A9="","",SUMIF(INDIRECT("'"&$B$2&"'!$C$4:$C$203"),$A9,INDIRECT("'"&$B$2&"'!$E$4:$E$203"))) | D9: =IF($A9="","",$B9-$C9) | E9: =IF($A9="","",IFERROR($C9/$B9,0)) | F9: =IF($A9="","",IF($B9=0,"—",IF($E9>1,"বেশি হয়ে গেছে",IF($E9>=0.8,"সতর্ক","ভালো"))))
C10: =IF($A10="","",SUMIF(INDIRECT("'"&$B$2&"'!$C$4:$C$203"),$A10,INDIRECT("'"&$B$2&"'!$E$4:$E$203"))) | D10: =IF($A10="","",$B10-$C10) | E10: =IF($A10="","",IFERROR($C10/$B10,0)) | F10: =IF($A10="","",IF($B10=0,"—",IF($E10>1,"বেশি হয়ে গেছে",IF($E10>=0.8,"সতর্ক","ভালো"))))
C11: =IF($A11="","",SUMIF(INDIRECT("'"&$B$2&"'!$C$4:$C$203"),$A11,INDIRECT("'"&$B$2&"'!$E$4:$E$203"))) | D11: =IF($A11="","",$B11-$C11) | E11: =IF($A11="","",IFERROR($C11/$B11,0)) | F11: =IF($A11="","",IF($B11=0,"—",IF($E11>1,"বেশি হয়ে গেছে",IF($E11>=0.8,"সতর্ক","ভালো"))))
C12: =IF($A12="","",SUMIF(INDIRECT("'"&$B$2&"'!$C$4:$C$203"),$A12,INDIRECT("'"&$B$2&"'!$E$4:$E$203"))) | D12: =IF($A12="","",$B12-$C12) | E12: =IF($A12="","",IFERROR($C12/$B12,0)) | F12: =IF($A12="","",IF($B12=0,"—",IF($E12>1,"বেশি হয়ে গেছে",IF($E12>=0.8,"সতর্ক","ভালো"))))
C13: =IF($A13="","",SUMIF(INDIRECT("'"&$B$2&"'!$C$4:$C$203"),$A13,INDIRECT("'"&$B$2&"'!$E$4:$E$203"))) | D13: =IF($A13="","",$B13-$C13) | E13: =IF($A13="","",IFERROR($C13/$B13,0)) | F13: =IF($A13="","",IF($B13=0,"—",IF($E13>1,"বেশি হয়ে গেছে",IF($E13>=0.8,"সতর্ক","ভালো"))))
C14: =IF($A14="","",SUMIF(INDIRECT("'"&$B$2&"'!$C$4:$C$203"),$A14,INDIRECT("'"&$B$2&"'!$E$4:$E$203"))) | D14: =IF($A14="","",$B14-$C14) | E14: =IF($A14="","",IFERROR($C14/$B14,0)) | F14: =IF($A14="","",IF($B14=0,"—",IF($E14>1,"বেশি হয়ে গেছে",IF($E14>=0.8,"সতর্ক","ভালো"))))
C15: =IF($A15="","",SUMIF(INDIRECT("'"&$B$2&"'!$C$4:$C$203"),$A15,INDIRECT("'"&$B$2&"'!$E$4:$E$203"))) | D15: =IF($A15="","",$B15-$C15) | E15: =IF($A15="","",IFERROR($C15/$B15,0)) | F15: =IF($A15="","",IF($B15=0,"—",IF($E15>1,"বেশি হয়ে গেছে",IF($E15>=0.8,"সতর্ক","ভালো"))))
... C53: =IF($A53="","",SUMIF(INDIRECT("'"&$B$2&"'!$C$4:$C$203"),$A53,INDIRECT("'"&$B$2&"'!$E$4:$E$203"))) | D53: =IF($A53="","",$B53-$C53) | E53: =IF($A53="","",IFERROR($C53/$B53,0)) | F53: =IF($A53="","",IF($B53=0,"—",IF($E53>1,"বেশি হয়ে গেছে",IF($E53>=0.8,"সতর্ক","ভালো"))))
A54: মোট | B54: =SUM($B$4:$B$53) | C54: =SUM($C$4:$C$53) | D54: =$B$54-$C$54 | E54: =IFERROR($C$54/$B$54,0)
A55: বাজেটবিহীন খাতে খরচ | C55: =IFERROR(INDIRECT("'"&$B$2&"'!$J$12")-$C$54,"")

Sheet পুনরাবৃত্ত খরচ
A1: পুনরাবৃত্ত খরচ — নিয়মিত বিল ও কিস্তি | L1: সারসংক্ষেপ
A2: অ্যাপ থেকে সিঙ্ক করলে এই শিটের ৪–১০৩ সারি সম্পূর্ণ নতুন করে লেখা হয়। ‘গ্রুপ’ ও ‘মাসিক সমমান’ কলাম স্বয়ংক্রিয় — এখানে কিছু লিখবেন না। এগুলো নিয়ম, খরচ নয়: প্রকৃত খরচ মাসিক শিটে যায়।
A3: খাত | B3: গ্রুপ | C3: পরিমাণ (৳) | D3: পেমেন্ট মাধ্যম | E3: বিবরণ | F3: কত দিন পর পর | G3: শুরুর তারিখ | H3: পরবর্তী | I3: চালু? | J3: মাসিক সমমান (৳) | L3: হিসাব | M3: মান
B4: =IFERROR(INDEX(GroupLookup,MATCH($A4,CategoryList,0)),"") | J4: =IF($A4="","",IF($I4<>"চালু",0,$C4*IF($F4="প্রতিদিন",30,IF($F4="প্রতি সপ্তাহে",4.33,IF($F4="প্রতি মাসে",1,IF($F4="প্রতি বছরে",1/12,0)))))) | L4: চালু নিয়ম | M4: =COUNTIF($I$4:$I$103,"চালু")
B5: =IFERROR(INDEX(GroupLookup,MATCH($A5,CategoryList,0)),"") | J5: =IF($A5="","",IF($I5<>"চালু",0,$C5*IF($F5="প্রতিদিন",30,IF($F5="প্রতি সপ্তাহে",4.33,IF($F5="প্রতি মাসে",1,IF($F5="প্রতি বছরে",1/12,0)))))) | L5: বন্ধ নিয়ম | M5: =COUNTIF($I$4:$I$103,"বন্ধ")
B6: =IFERROR(INDEX(GroupLookup,MATCH($A6,CategoryList,0)),"") | J6: =IF($A6="","",IF($I6<>"চালু",0,$C6*IF($F6="প্রতিদিন",30,IF($F6="প্রতি সপ্তাহে",4.33,IF($F6="প্রতি মাসে",1,IF($F6="প্রতি বছরে",1/12,0)))))) | L6: মোট মাসিক প্রতিশ্রুতি | M6: =SUM($J$4:$J$103)
B7: =IFERROR(INDEX(GroupLookup,MATCH($A7,CategoryList,0)),"") | J7: =IF($A7="","",IF($I7<>"চালু",0,$C7*IF($F7="প্রতিদিন",30,IF($F7="প্রতি সপ্তাহে",4.33,IF($F7="প্রতি মাসে",1,IF($F7="প্রতি বছরে",1/12,0)))))) | L7: মোট বার্ষিক প্রতিশ্রুতি | M7: =$M$6*12
B8: =IFERROR(INDEX(GroupLookup,MATCH($A8,CategoryList,0)),"") | J8: =IF($A8="","",IF($I8<>"চালু",0,$C8*IF($F8="প্রতিদিন",30,IF($F8="প্রতি সপ্তাহে",4.33,IF($F8="প্রতি মাসে",1,IF($F8="প্রতি বছরে",1/12,0)))))) | L8: পরবর্তী তারিখ পেরিয়ে গেছে | M8: =COUNTIFS($I$4:$I$103,"চালু",$H$4:$H$103,"<"&TODAY())
B9: =IFERROR(INDEX(GroupLookup,MATCH($A9,CategoryList,0)),"") | J9: =IF($A9="","",IF($I9<>"চালু",0,$C9*IF($F9="প্রতিদিন",30,IF($F9="প্রতি সপ্তাহে",4.33,IF($F9="প্রতি মাসে",1,IF($F9="প্রতি বছরে",1/12,0))))))
B10: =IFERROR(INDEX(GroupLookup,MATCH($A10,CategoryList,0)),"") | J10: =IF($A10="","",IF($I10<>"চালু",0,$C10*IF($F10="প্রতিদিন",30,IF($F10="প্রতি সপ্তাহে",4.33,IF($F10="প্রতি মাসে",1,IF($F10="প্রতি বছরে",1/12,0))))))
B11: =IFERROR(INDEX(GroupLookup,MATCH($A11,CategoryList,0)),"") | J11: =IF($A11="","",IF($I11<>"চালু",0,$C11*IF($F11="প্রতিদিন",30,IF($F11="প্রতি সপ্তাহে",4.33,IF($F11="প্রতি মাসে",1,IF($F11="প্রতি বছরে",1/12,0))))))
B12: =IFERROR(INDEX(GroupLookup,MATCH($A12,CategoryList,0)),"") | J12: =IF($A12="","",IF($I12<>"চালু",0,$C12*IF($F12="প্রতিদিন",30,IF($F12="প্রতি সপ্তাহে",4.33,IF($F12="প্রতি মাসে",1,IF($F12="প্রতি বছরে",1/12,0))))))
B13: =IFERROR(INDEX(GroupLookup,MATCH($A13,CategoryList,0)),"") | J13: =IF($A13="","",IF($I13<>"চালু",0,$C13*IF($F13="প্রতিদিন",30,IF($F13="প্রতি সপ্তাহে",4.33,IF($F13="প্রতি মাসে",1,IF($F13="প্রতি বছরে",1/12,0))))))
B14: =IFERROR(INDEX(GroupLookup,MATCH($A14,CategoryList,0)),"") | J14: =IF($A14="","",IF($I14<>"চালু",0,$C14*IF($F14="প্রতিদিন",30,IF($F14="প্রতি সপ্তাহে",4.33,IF($F14="প্রতি মাসে",1,IF($F14="প্রতি বছরে",1/12,0))))))
B15: =IFERROR(INDEX(GroupLookup,MATCH($A15,CategoryList,0)),"") | J15: =IF($A15="","",IF($I15<>"চালু",0,$C15*IF($F15="প্রতিদিন",30,IF($F15="প্রতি সপ্তাহে",4.33,IF($F15="প্রতি মাসে",1,IF($F15="প্রতি বছরে",1/12,0))))))
B16: =IFERROR(INDEX(GroupLookup,MATCH($A16,CategoryList,0)),"") | J16: =IF($A16="","",IF($I16<>"চালু",0,$C16*IF($F16="প্রতিদিন",30,IF($F16="প্রতি সপ্তাহে",4.33,IF($F16="প্রতি মাসে",1,IF($F16="প্রতি বছরে",1/12,0))))))
B17: =IFERROR(INDEX(GroupLookup,MATCH($A17,CategoryList,0)),"") | J17: =IF($A17="","",IF($I17<>"চালু",0,$C17*IF($F17="প্রতিদিন",30,IF($F17="প্রতি সপ্তাহে",4.33,IF($F17="প্রতি মাসে",1,IF($F17="প্রতি বছরে",1/12,0))))))
B18: =IFERROR(INDEX(GroupLookup,MATCH($A18,CategoryList,0)),"") | J18: =IF($A18="","",IF($I18<>"চালু",0,$C18*IF($F18="প্রতিদিন",30,IF($F18="প্রতি সপ্তাহে",4.33,IF($F18="প্রতি মাসে",1,IF($F18="প্রতি বছরে",1/12,0))))))
B19: =IFERROR(INDEX(GroupLookup,MATCH($A19,CategoryList,0)),"") | J19: =IF($A19="","",IF($I19<>"চালু",0,$C19*IF($F19="প্রতিদিন",30,IF($F19="প্রতি সপ্তাহে",4.33,IF($F19="প্রতি মাসে",1,IF($F19="প্রতি বছরে",1/12,0))))))
B20: =IFERROR(INDEX(GroupLookup,MATCH($A20,CategoryList,0)),"") | J20: =IF($A20="","",IF($I20<>"চালু",0,$C20*IF($F20="প্রতিদিন",30,IF($F20="প্রতি সপ্তাহে",4.33,IF($F20="প্রতি মাসে",1,IF($F20="প্রতি বছরে",1/12,0))))))
... B103: =IFERROR(INDEX(GroupLookup,MATCH($A103,CategoryList,0)),"") | J103: =IF($A103="","",IF($I103<>"চালু",0,$C103*IF($F103="প্রতিদিন",30,IF($F103="প্রতি সপ্তাহে",4.33,IF($F103="প্রতি মাসে",1,IF($F103="প্রতি বছরে",1/12,0))))))

Sheet সেটিংস
A1: ক্রমিক | B1: খাত (উপশ্রেণি) | C1: গ্রুপ (প্রধান খাত) | E1: গ্রুপ তালিকা | G1: পেমেন্ট মাধ্যম | I1: মাসিক শিটের তালিকা
A2: 1 | B2: চাল | C2: খাদ্য ও মুদি | E2: খাদ্য ও মুদি | G2: নগদ টাকা | I2: জানুয়ারি ২০২৬
A3: 2 | B3: আটা ও ময়দা | C3: খাদ্য ও মুদি | E3: বাসস্থান | G3: বিকাশ | I3: ফেব্রুয়ারি ২০২৬
A4: 3 | B4: ডাল | C4: খাদ্য ও মুদি | E4: ইউটিলিটি বিল | G4: নগদ (অ্যাপ) | I4: মার্চ ২০২৬
A5: 4 | B5: মাছ | C5: খাদ্য ও মুদি | E5: যাতায়াত | G5: রকেট | I5: এপ্রিল ২০২৬
A6: 5 | B6: মাংস | C6: খাদ্য ও মুদি | E6: স্বাস্থ্য | G6: ডেবিট / ক্রেডিট কার্ড | I6: মে ২০২৬
A7: 6 | B7: ডিম | C7: খাদ্য ও মুদি | E7: শিক্ষা | G7: ব্যাংক ট্রান্সফার | I7: জুন ২০২৬
A8: 7 | B8: দুধ ও দুগ্ধজাত পণ্য | C8: খাদ্য ও মুদি | E8: ব্যক্তিগত ও গৃহস্থালি | I8: জুলাই ২০২৬
A9: 8 | B9: ভোজ্য তেল | C9: খাদ্য ও মুদি | E9: অন্যান্য | I9: আগস্ট ২০২৬
A10: 9 | B10: শাক-সবজি | C10: খাদ্য ও মুদি | I10: সেপ্টেম্বর ২০২৬
A11: 10 | B11: ফলমূল | C11: খাদ্য ও মুদি | I11: অক্টোবর ২০২৬
A12: 11 | B12: মসলা | C12: খাদ্য ও মুদি | I12: নভেম্বর ২০২৬
A13: 12 | B13: চিনি ও লবণ | C13: খাদ্য ও মুদি | I13: ডিসেম্বর ২০২৬
A14: 13 | B14: চা ও কফি | C14: খাদ্য ও মুদি
A15: 14 | B15: নাশতা ও বেকারি | C15: খাদ্য ও মুদি
A16: 15 | B16: বাইরে খাওয়া / রেস্তোরাঁ | C16: খাদ্য ও মুদি
A17: 16 | B17: বাড়ি ভাড়া | C17: বাসস্থান
A18: 17 | B18: সার্ভিস চার্জ | C18: বাসস্থান
A19: 18 | B19: বাড়ি মেরামত ও রক্ষণাবেক্ষণ | C19: বাসস্থান
A20: 19 | B20: গৃহকর্মীর বেতন | C20: বাসস্থান
A21: 20 | B21: আসবাবপত্র | C21: বাসস্থান
A22: 21 | B22: বিদ্যুৎ বিল | C22: ইউটিলিটি বিল
A23: 22 | B23: গ্যাস বিল | C23: ইউটিলিটি বিল
A24: 23 | B24: পানির বিল | C24: ইউটিলিটি বিল
A25: 24 | B25: ইন্টারনেট বিল | C25: ইউটিলিটি বিল
... A55: 54 | B55: অন্যান্য খরচ | C55: অন্যান্য

Sheet জানুয়ারি ২০২৬
A1: দৈনিক খরচের হিসাব — জানুয়ারি ২০২৬ | I1: মাসিক সারসংক্ষেপ
A2: শুধু তারিখ · বিবরণ · খাত · পরিমাণ · পেমেন্ট মাধ্যম · মন্তব্য ঘরগুলো পূরণ করুন। ‘গ্রুপ’ কলাম স্বয়ংক্রিয়ভাবে পূরণ হবে।
A3: তারিখ | B3: বিবরণ | C3: খাত | D3: গ্রুপ | E3: পরিমাণ (৳) | F3: পেমেন্ট মাধ্যম | G3: মন্তব্য | I3: গ্রুপ (প্রধান খাত) | J3: মোট (৳) | K3: শতাংশ
D4: {=IFERROR(INDEX(GroupLookup,MATCH(C4,CategoryList,0)),"")} | I4: খাদ্য ও মুদি | J4: =SUMIF($D$4:$D$203,$I4,$E$4:$E$203) | K4: =IFERROR($J4/$J$12,0)
D5: {=IFERROR(INDEX(GroupLookup,MATCH(C5,CategoryList,0)),"")} | I5: বাসস্থান | J5: =SUMIF($D$4:$D$203,$I5,$E$4:$E$203) | K5: =IFERROR($J5/$J$12,0)
D6: {=IFERROR(INDEX(GroupLookup,MATCH(C6,CategoryList,0)),"")} | I6: ইউটিলিটি বিল | J6: =SUMIF($D$4:$D$203,$I6,$E$4:$E$203) | K6: =IFERROR($J6/$J$12,0)
D7: {=IFERROR(INDEX(GroupLookup,MATCH(C7,CategoryList,0)),"")} | I7: যাতায়াত | J7: =SUMIF($D$4:$D$203,$I7,$E$4:$E$203) | K7: =IFERROR($J7/$J$12,0)
D8: {=IFERROR(INDEX(GroupLookup,MATCH(C8,CategoryList,0)),"")} | I8: স্বাস্থ্য | J8: =SUMIF($D$4:$D$203,$I8,$E$4:$E$203) | K8: =IFERROR($J8/$J$12,0)
D9: {=IFERROR(INDEX(GroupLookup,MATCH(C9,CategoryList,0)),"")} | I9: শিক্ষা | J9: =SUMIF($D$4:$D$203,$I9,$E$4:$E$203) | K9: =IFERROR($J9/$J$12,0)
D10: {=IFERROR(INDEX(GroupLookup,MATCH(C10,CategoryList,0)),"")} | I10: ব্যক্তিগত ও গৃহস্থালি | J10: =SUMIF($D$4:$D$203,$I10,$E$4:$E$203) | K10: =IFERROR($J10/$J$12,0)
D11: {=IFERROR(INDEX(GroupLookup,MATCH(C11,CategoryList,0)),"")} | I11: অন্যান্য | J11: =SUMIF($D$4:$D$203,$I11,$E$4:$E$203) | K11: =IFERROR($J11/$J$12,0)
D12: {=IFERROR(INDEX(GroupLookup,MATCH(C12,CategoryList,0)),"")} | I12: মোট মাসিক ব্যয় | J12: =SUM($E$4:$E$203) | K12: =IFERROR($J$12/$J$12,0)
D13: {=IFERROR(INDEX(GroupLookup,MATCH(C13,CategoryList,0)),"")} | I13: শ্রেণিবিন্যাসহীন (খাত তালিকায় নেই) | J13: =$J$12-SUM($J$4:$J$11) | K13: =IFERROR($J13/$J$12,0)
D14: {=IFERROR(INDEX(GroupLookup,MATCH(C14,CategoryList,0)),"")} | I14: গুরুত্বপূর্ণ তথ্য
D15: {=IFERROR(INDEX(GroupLookup,MATCH(C15,CategoryList,0)),"")} | I15: মোট লেনদেন সংখ্যা | J15: =COUNT($E$4:$E$203)
D16: {=IFERROR(INDEX(GroupLookup,MATCH(C16,CategoryList,0)),"")} | I16: দৈনিক গড় খরচ | J16: =IFERROR($J$12/31,0)
D17: {=IFERROR(INDEX(GroupLookup,MATCH(C17,CategoryList,0)),"")} | I17: প্রতি লেনদেনে গড় | J17: =IFERROR($J$12/COUNT($E$4:$E$203),0)
D18: {=IFERROR(INDEX(GroupLookup,MATCH(C18,CategoryList,0)),"")} | I18: সর্বোচ্চ একক খরচ | J18: =IFERROR(MAX($E$4:$E$203),0)
D19: {=IFERROR(INDEX(GroupLookup,MATCH(C19,CategoryList,0)),"")} | I19: সর্বোচ্চ ব্যয়ের গ্রুপ | J19: {=IF($J$12=0,"–",IFERROR(INDEX($I$4:$I$11,MATCH(MAX($J$4:$J$11),$J$4:$J$11,0)),"–"))}
D20: {=IFERROR(INDEX(GroupLookup,MATCH(C20,CategoryList,0)),"")} | I20: সর্বোচ্চ ব্যয়ের খাত | J20: {=IF($J$12=0,"–",IFERROR(INDEX($I$23:$I$76,MATCH(MAX($J$23:$J$76),$J$23:$J$76,0)),"–"))}
D21: {=IFERROR(INDEX(GroupLookup,MATCH(C21,CategoryList,0)),"")} | I21: খাতভিত্তিক বিস্তারিত
D22: {=IFERROR(INDEX(GroupLookup,MATCH(C22,CategoryList,0)),"")} | I22: খাত | J22: মোট (৳) | K22: শতাংশ
D23: {=IFERROR(INDEX(GroupLookup,MATCH(C23,CategoryList,0)),"")} | I23: চাল | J23: =SUMIF($C$4:$C$203,$I23,$E$4:$E$203) | K23: =IFERROR($J23/$J$12,0)
D24: {=IFERROR(INDEX(GroupLookup,MATCH(C24,CategoryList,0)),"")} | I24: আটা ও ময়দা | J24: =SUMIF($C$4:$C$203,$I24,$E$4:$E$203) | K24: =IFERROR($J24/$J$12,0)
D25: {=IFERROR(INDEX(GroupLookup,MATCH(C25,CategoryList,0)),"")} | I25: ডাল | J25: =SUMIF($C$4:$C$203,$I25,$E$4:$E$203) | K25: =IFERROR($J25/$J$12,0)
D26: {=IFERROR(INDEX(GroupLookup,MATCH(C26,CategoryList,0)),"")} | I26: মাছ | J26: =SUMIF($C$4:$C$203,$I26,$E$4:$E$203) | K26: =IFERROR($J26/$J$12,0)
D27: {=IFERROR(INDEX(GroupLookup,MATCH(C27,CategoryList,0)),"")} | I27: মাংস | J27: =SUMIF($C$4:$C$203,$I27,$E$4:$E$203) | K27: =IFERROR($J27/$J$12,0)
D28: {=IFERROR(INDEX(GroupLookup,MATCH(C28,CategoryList,0)),"")} | I28: ডিম | J28: =SUMIF($C$4:$C$203,$I28,$E$4:$E$203) | K28: =IFERROR($J28/$J$12,0)
D29: {=IFERROR(INDEX(GroupLookup,MATCH(C29,CategoryList,0)),"")} | I29: দুধ ও দুগ্ধজাত পণ্য | J29: =SUMIF($C$4:$C$203,$I29,$E$4:$E$203) | K29: =IFERROR($J29/$J$12,0)
D30: {=IFERROR(INDEX(GroupLookup,MATCH(C30,CategoryList,0)),"")} | I30: ভোজ্য তেল | J30: =SUMIF($C$4:$C$203,$I30,$E$4:$E$203) | K30: =IFERROR($J30/$J$12,0)
D31: {=IFERROR(INDEX(GroupLookup,MATCH(C31,CategoryList,0)),"")} | I31: শাক-সবজি | J31: =SUMIF($C$4:$C$203,$I31,$E$4:$E$203) | K31: =IFERROR($J31/$J$12,0)
D32: {=IFERROR(INDEX(GroupLookup,MATCH(C32,CategoryList,0)),"")} | I32: ফলমূল | J32: =SUMIF($C$4:$C$203,$I32,$E$4:$E$203) | K32: =IFERROR($J32/$J$12,0)
D33: {=IFERROR(INDEX(GroupLookup,MATCH(C33,CategoryList,0)),"")} | I33: মসলা | J33: =SUMIF($C$4:$C$203,$I33,$E$4:$E$203) | K33: =IFERROR($J33/$J$12,0)
D34: {=IFERROR(INDEX(GroupLookup,MATCH(C34,CategoryList,0)),"")} | I34: চিনি ও লবণ | J34: =SUMIF($C$4:$C$203,$I34,$E$4:$E$203) | K34: =IFERROR($J34/$J$12,0)
... D76: {=IFERROR(INDEX(GroupLookup,MATCH(C76,CategoryList,0)),"")} | I76: অন্যান্য খরচ | J76: =SUMIF($C$4:$C$203,$I76,$E$4:$E$203) | K76: =IFERROR($J76/$J$12,0)
D77: {=IFERROR(INDEX(GroupLookup,MATCH(C77,CategoryList,0)),"")} | I77: সর্বমোট | J77: =SUM($J$23:$J$76) | K77: =IFERROR($J$77/$J$12,0)
D78: {=IFERROR(INDEX(GroupLookup,MATCH(C78,CategoryList,0)),"")}
D79: {=IFERROR(INDEX(GroupLookup,MATCH(C79,CategoryList,0)),"")}
D80: {=IFERROR(INDEX(GroupLookup,MATCH(C80,CategoryList,0)),"")}
D81: {=IFERROR(INDEX(GroupLookup,MATCH(C81,CategoryList,0)),"")}
...

Sheet ফেব্রুয়ারি ২০২৬
A1: দৈনিক খরচের হিসাব — ফেব্রুয়ারি ২০২৬ | I1: মাসিক সারসংক্ষেপ
A2: শুধু তারিখ · বিবরণ · খাত · পরিমাণ · পেমেন্ট মাধ্যম · মন্তব্য ঘরগুলো পূরণ করুন। ‘গ্রুপ’ কলাম স্বয়ংক্রিয়ভাবে পূরণ হবে।
A3: তারিখ | B3: বিবরণ | C3: খাত | D3: গ্রুপ | E3: পরিমাণ (৳) | F3: পেমেন্ট মাধ্যম | G3: মন্তব্য | I3: গ্রুপ (প্রধান খাত) | J3: মোট (৳) | K3: শতাংশ
D4: {=IFERROR(INDEX(GroupLookup,MATCH(C4,CategoryList,0)),"")} | I4: খাদ্য ও মুদি | J4: =SUMIF($D$4:$D$203,$I4,$E$4:$E$203) | K4: =IFERROR($J4/$J$12,0)
D5: {=IFERROR(INDEX(GroupLookup,MATCH(C5,CategoryList,0)),"")} | I5: বাসস্থান | J5: =SUMIF($D$4:$D$203,$I5,$E$4:$E$203) | K5: =IFERROR($J5/$J$12,0)
D6: {=IFERROR(INDEX(GroupLookup,MATCH(C6,CategoryList,0)),"")} | I6: ইউটিলিটি বিল | J6: =SUMIF($D$4:$D$203,$I6,$E$4:$E$203) | K6: =IFERROR($J6/$J$12,0)
D7: {=IFERROR(INDEX(GroupLookup,MATCH(C7,CategoryList,0)),"")} | I7: যাতায়াত | J7: =SUMIF($D$4:$D$203,$I7,$E$4:$E$203) | K7: =IFERROR($J7/$J$12,0)
D8: {=IFERROR(INDEX(GroupLookup,MATCH(C8,CategoryList,0)),"")} | I8: স্বাস্থ্য | J8: =SUMIF($D$4:$D$203,$I8,$E$4:$E$203) | K8: =IFERROR($J8/$J$12,0)
D9: {=IFERROR(INDEX(GroupLookup,MATCH(C9,CategoryList,0)),"")} | I9: শিক্ষা | J9: =SUMIF($D$4:$D$203,$I9,$E$4:$E$203) | K9: =IFERROR($J9/$J$12,0)
D10: {=IFERROR(INDEX(GroupLookup,MATCH(C10,CategoryList,0)),"")} | I10: ব্যক্তিগত ও গৃহস্থালি | J10: =SUMIF($D$4:$D$203,$I10,$E$4:$E$203) | K10: =IFERROR($J10/$J$12,0)
D11: {=IFERROR(INDEX(GroupLookup,MATCH(C11,CategoryList,0)),"")} | I11: অন্যান্য | J11: =SUMIF($D$4:$D$203,$I11,$E$4:$E$203) | K11: =IFERROR($J11/$J$12,0)
D12: {=IFERROR(INDEX(GroupLookup,MATCH(C12,CategoryList,0)),"")} | I12: মোট মাসিক ব্যয় | J12: =SUM($E$4:$E$203) | K12: =IFERROR($J$12/$J$12,0)
D13: {=IFERROR(INDEX(GroupLookup,MATCH(C13,CategoryList,0)),"")} | I13: শ্রেণিবিন্যাসহীন (খাত তালিকায় নেই) | J13: =$J$12-SUM($J$4:$J$11) | K13: =IFERROR($J13/$J$12,0)
D14: {=IFERROR(INDEX(GroupLookup,MATCH(C14,CategoryList,0)),"")} | I14: গুরুত্বপূর্ণ তথ্য
D15: {=IFERROR(INDEX(GroupLookup,MATCH(C15,CategoryList,0)),"")} | I15: মোট লেনদেন সংখ্যা | J15: =COUNT($E$4:$E$203)
D16: {=IFERROR(INDEX(GroupLookup,MATCH(C16,CategoryList,0)),"")} | I16: দৈনিক গড় খরচ | J16: =IFERROR($J$12/28,0)
D17: {=IFERROR(INDEX(GroupLookup,MATCH(C17,CategoryList,0)),"")} | I17: প্রতি লেনদেনে গড় | J17: =IFERROR($J$12/COUNT($E$4:$E$203),0)
D18: {=IFERROR(INDEX(GroupLookup,MATCH(C18,CategoryList,0)),"")} | I18: সর্বোচ্চ একক খরচ | J18: =IFERROR(MAX($E$4:$E$203),0)
D19: {=IFERROR(INDEX(GroupLookup,MATCH(C19,CategoryList,0)),"")} | I19: সর্বোচ্চ ব্যয়ের গ্রুপ | J19: {=IF($J$12=0,"–",IFERROR(INDEX($I$4:$I$11,MATCH(MAX($J$4:$J$11),$J$4:$J$11,0)),"–"))}
D20: {=IFERROR(INDEX(GroupLookup,MATCH(C20,CategoryList,0)),"")} | I20: সর্বোচ্চ ব্যয়ের খাত | J20: {=IF($J$12=0,"–",IFERROR(INDEX($I$23:$I$76,MATCH(MAX($J$23:$J$76),$J$23:$J$76,0)),"–"))}
D21: {=IFERROR(INDEX(GroupLookup,MATCH(C21,CategoryList,0)),"")} | I21: খাতভিত্তিক বিস্তারিত
D22: {=IFERROR(INDEX(GroupLookup,MATCH(C22,CategoryList,0)),"")} | I22: খাত | J22: মোট (৳) | K22: শতাংশ
D23: {=IFERROR(INDEX(GroupLookup,MATCH(C23,CategoryList,0)),"")} | I23: চাল | J23: =SUMIF($C$4:$C$203,$I23,$E$4:$E$203) | K23: =IFERROR($J23/$J$12,0)
D24: {=IFERROR(INDEX(GroupLookup,MATCH(C24,CategoryList,0)),"")} | I24: আটা ও ময়দা | J24: =SUMIF($C$4:$C$203,$I24,$E$4:$E$203) | K24: =IFERROR($J24/$J$12,0)
D25: {=IFERROR(INDEX(GroupLookup,MATCH(C25,CategoryList,0)),"")} | I25: ডাল | J25: =SUMIF($C$4:$C$203,$I25,$E$4:$E$203) | K25: =IFERROR($J25/$J$12,0)
D26: {=IFERROR(INDEX(GroupLookup,MATCH(C26,CategoryList,0)),"")} | I26: মাছ | J26: =SUMIF($C$4:$C$203,$I26,$E$4:$E$203) | K26: =IFERROR($J26/$J$12,0)
D27: {=IFERROR(INDEX(GroupLookup,MATCH(C27,CategoryList,0)),"")} | I27: মাংস | J27: =SUMIF($C$4:$C$203,$I27,$E$4:$E$203) | K27: =IFERROR($J27/$J$12,0)
D28: {=IFERROR(INDEX(GroupLookup,MATCH(C28,CategoryList,0)),"")} | I28: ডিম | J28: =SUMIF($C$4:$C$203,$I28,$E$4:$E$203) | K28: =IFERROR($J28/$J$12,0)
D29: {=IFERROR(INDEX(GroupLookup,MATCH(C29,CategoryList,0)),"")} | I29: দুধ ও দুগ্ধজাত পণ্য | J29: =SUMIF($C$4:$C$203,$I29,$E$4:$E$203) | K29: =IFERROR($J29/$J$12,0)
D30: {=IFERROR(INDEX(GroupLookup,MATCH(C30,CategoryList,0)),"")} | I30: ভোজ্য তেল | J30: =SUMIF($C$4:$C$203,$I30,$E$4:$E$203) | K30: =IFERROR($J30/$J$12,0)
D31: {=IFERROR(INDEX(GroupLookup,MATCH(C31,CategoryList,0)),"")} | I31: শাক-সবজি | J31: =SUMIF($C$4:$C$203,$I31,$E$4:$E$203) | K31: =IFERROR($J31/$J$12,0)
D32: {=IFERROR(INDEX(GroupLookup,MATCH(C32,CategoryList,0)),"")} | I32: ফলমূল | J32: =SUMIF($C$4:$C$203,$I32,$E$4:$E$203) | K32: =IFERROR($J32/$J$12,0)
D33: {=IFERROR(INDEX(GroupLookup,MATCH(C33,CategoryList,0)),"")} | I33: মসলা | J33: =SUMIF($C$4:$C$203,$I33,$E$4:$E$203) | K33: =IFERROR($J33/$J$12,0)
D34: {=IFERROR(INDEX(GroupLookup,MATCH(C34,CategoryList,0)),"")} | I34: চিনি ও লবণ | J34: =SUMIF($C$4:$C$203,$I34,$E$4:$E$203) | K34: =IFERROR($J34/$J$12,0)
... D76: {=IFERROR(INDEX(GroupLookup,MATCH(C76,CategoryList,0)),"")} | I76: অন্যান্য খরচ | J76: =SUMIF($C$4:$C$203,$I76,$E$4:$E$203) | K76: =IFERROR($J76/$J$12,0)
D77: {=IFERROR(INDEX(GroupLookup,MATCH(C77,CategoryList,0)),"")} | I77: সর্বমোট | J77: =SUM($J$23:$J$76) | K77: =IFERROR($J$77/$J$12,0)
D78: {=IFERROR(INDEX(GroupLookup,MATCH(C78,CategoryList,0)),"")}
D79: {=IFERROR(INDEX(GroupLookup,MATCH(C79,CategoryList,0)),"")}
D80: {=IFERROR(INDEX(GroupLookup,MATCH(C80,CategoryList,0)),"")}
D81: {=IFERROR(INDEX(GroupLookup,MATCH(C81,CategoryList,0)),"")}
...

Sheet মার্চ ২০২৬
A1: দৈনিক খরচের হিসাব — মার্চ ২০২৬ | I1: মাসিক সারসংক্ষেপ
A2: শুধু তারিখ · বিবরণ · খাত · পরিমাণ · পেমেন্ট মাধ্যম · মন্তব্য ঘরগুলো পূরণ করুন। ‘গ্রুপ’ কলাম স্বয়ংক্রিয়ভাবে পূরণ হবে।
A3: তারিখ | B3: বিবরণ | C3: খাত | D3: গ্রুপ | E3: পরিমাণ (৳) | F3: পেমেন্ট মাধ্যম | G3: মন্তব্য | I3: গ্রুপ (প্রধান খাত) | J3: মোট (৳) | K3: শতাংশ
D4: {=IFERROR(INDEX(GroupLookup,MATCH(C4,CategoryList,0)),"")} | I4: খাদ্য ও মুদি | J4: =SUMIF($D$4:$D$203,$I4,$E$4:$E$203) | K4: =IFERROR($J4/$J$12,0)
D5: {=IFERROR(INDEX(GroupLookup,MATCH(C5,CategoryList,0)),"")} | I5: বাসস্থান | J5: =SUMIF($D$4:$D$203,$I5,$E$4:$E$203) | K5: =IFERROR($J5/$J$12,0)
D6: {=IFERROR(INDEX(GroupLookup,MATCH(C6,CategoryList,0)),"")} | I6: ইউটিলিটি বিল | J6: =SUMIF($D$4:$D$203,$I6,$E$4:$E$203) | K6: =IFERROR($J6/$J$12,0)
D7: {=IFERROR(INDEX(GroupLookup,MATCH(C7,CategoryList,0)),"")} | I7: যাতায়াত | J7: =SUMIF($D$4:$D$203,$I7,$E$4:$E$203) | K7: =IFERROR($J7/$J$12,0)
D8: {=IFERROR(INDEX(GroupLookup,MATCH(C8,CategoryList,0)),"")} | I8: স্বাস্থ্য | J8: =SUMIF($D$4:$D$203,$I8,$E$4:$E$203) | K8: =IFERROR($J8/$J$12,0)
D9: {=IFERROR(INDEX(GroupLookup,MATCH(C9,CategoryList,0)),"")} | I9: শিক্ষা | J9: =SUMIF($D$4:$D$203,$I9,$E$4:$E$203) | K9: =IFERROR($J9/$J$12,0)
D10: {=IFERROR(INDEX(GroupLookup,MATCH(C10,CategoryList,0)),"")} | I10: ব্যক্তিগত ও গৃহস্থালি | J10: =SUMIF($D$4:$D$203,$I10,$E$4:$E$203) | K10: =IFERROR($J10/$J$12,0)
D11: {=IFERROR(INDEX(GroupLookup,MATCH(C11,CategoryList,0)),"")} | I11: অন্যান্য | J11: =SUMIF($D$4:$D$203,$I11,$E$4:$E$203) | K11: =IFERROR($J11/$J$12,0)
D12: {=IFERROR(INDEX(GroupLookup,MATCH(C12,CategoryList,0)),"")} | I12: মোট মাসিক ব্যয় | J12: =SUM($E$4:$E$203) | K12: =IFERROR($J$12/$J$12,0)
D13: {=IFERROR(INDEX(GroupLookup,MATCH(C13,CategoryList,0)),"")} | I13: শ্রেণিবিন্যাসহীন (খাত তালিকায় নেই) | J13: =$J$12-SUM($J$4:$J$11) | K13: =IFERROR($J13/$J$12,0)
D14: {=IFERROR(INDEX(GroupLookup,MATCH(C14,CategoryList,0)),"")} | I14: গুরুত্বপূর্ণ তথ্য
D15: {=IFERROR(INDEX(GroupLookup,MATCH(C15,CategoryList,0)),"")} | I15: মোট লেনদেন সংখ্যা | J15: =COUNT($E$4:$E$203)
D16: {=IFERROR(INDEX(GroupLookup,MATCH(C16,CategoryList,0)),"")} | I16: দৈনিক গড় খরচ | J16: =IFERROR($J$12/31,0)
D17: {=IFERROR(INDEX(GroupLookup,MATCH(C17,CategoryList,0)),"")} | I17: প্রতি লেনদেনে গড় | J17: =IFERROR($J$12/COUNT($E$4:$E$203),0)
D18: {=IFERROR(INDEX(GroupLookup,MATCH(C18,CategoryList,0)),"")} | I18: সর্বোচ্চ একক খরচ | J18: =IFERROR(MAX($E$4:$E$203),0)
D19: {=IFERROR(INDEX(GroupLookup,MATCH(C19,CategoryList,0)),"")} | I19: সর্বোচ্চ ব্যয়ের গ্রুপ | J19: {=IF($J$12=0,"–",IFERROR(INDEX($I$4:$I$11,MATCH(MAX($J$4:$J$11),$J$4:$J$11,0)),"–"))}
D20: {=IFERROR(INDEX(GroupLookup,MATCH(C20,CategoryList,0)),"")} | I20: সর্বোচ্চ ব্যয়ের খাত | J20: {=IF($J$12=0,"–",IFERROR(INDEX($I$23:$I$76,MATCH(MAX($J$23:$J$76),$J$23:$J$76,0)),"–"))}
D21: {=IFERROR(INDEX(GroupLookup,MATCH(C21,CategoryList,0)),"")} | I21: খাতভিত্তিক বিস্তারিত
D22: {=IFERROR(INDEX(GroupLookup,MATCH(C22,CategoryList,0)),"")} | I22: খাত | J22: মোট (৳) | K22: শতাংশ
D23: {=IFERROR(INDEX(GroupLookup,MATCH(C23,CategoryList,0)),"")} | I23: চাল | J23: =SUMIF($C$4:$C$203,$I23,$E$4:$E$203) | K23: =IFERROR($J23/$J$12,0)
D24: {=IFERROR(INDEX(GroupLookup,MATCH(C24,CategoryList,0)),"")} | I24: আটা ও ময়দা | J24: =SUMIF($C$4:$C$203,$I24,$E$4:$E$203) | K24: =IFERROR($J24/$J$12,0)
D25: {=IFERROR(INDEX(GroupLookup,MATCH(C25,CategoryList,0)),"")} | I25: ডাল | J25: =SUMIF($C$4:$C$203,$I25,$E$4:$E$203) | K25: =IFERROR($J25/$J$12,0)
D26: {=IFERROR(INDEX(GroupLookup,MATCH(C26,CategoryList,0)),"")} | I26: মাছ | J26: =SUMIF($C$4:$C$203,$I26,$E$4:$E$203) | K26: =IFERROR($J26/$J$12,0)
D27: {=IFERROR(INDEX(GroupLookup,MATCH(C27,CategoryList,0)),"")} | I27: মাংস | J27: =SUMIF($C$4:$C$203,$I27,$E$4:$E$203) | K27: =IFERROR($J27/$J$12,0)
D28: {=IFERROR(INDEX(GroupLookup,MATCH(C28,CategoryList,0)),"")} | I28: ডিম | J28: =SUMIF($C$4:$C$203,$I28,$E$4:$E$203) | K28: =IFERROR($J28/$J$12,0)
D29: {=IFERROR(INDEX(GroupLookup,MATCH(C29,CategoryList,0)),"")} | I29: দুধ ও দুগ্ধজাত পণ্য | J29: =SUMIF($C$4:$C$203,$I29,$E$4:$E$203) | K29: =IFERROR($J29/$J$12,0)
D30: {=IFERROR(INDEX(GroupLookup,MATCH(C30,CategoryList,0)),"")} | I30: ভোজ্য তেল | J30: =SUMIF($C$4:$C$203,$I30,$E$4:$E$203) | K30: =IFERROR($J30/$J$12,0)
D31: {=IFERROR(INDEX(GroupLookup,MATCH(C31,CategoryList,0)),"")} | I31: শাক-সবজি | J31: =SUMIF($C$4:$C$203,$I31,$E$4:$E$203) | K31: =IFERROR($J31/$J$12,0)
D32: {=IFERROR(INDEX(GroupLookup,MATCH(C32,CategoryList,0)),"")} | I32: ফলমূল | J32: =SUMIF($C$4:$C$203,$I32,$E$4:$E$203) | K32: =IFERROR($J32/$J$12,0)
D33: {=IFERROR(INDEX(GroupLookup,MATCH(C33,CategoryList,0)),"")} | I33: মসলা | J33: =SUMIF($C$4:$C$203,$I33,$E$4:$E$203) | K33: =IFERROR($J33/$J$12,0)
D34: {=IFERROR(INDEX(GroupLookup,MATCH(C34,CategoryList,0)),"")} | I34: চিনি ও লবণ | J34: =SUMIF($C$4:$C$203,$I34,$E$4:$E$203) | K34: =IFERROR($J34/$J$12,0)
... D76: {=IFERROR(INDEX(GroupLookup,MATCH(C76,CategoryList,0)),"")} | I76: অন্যান্য খরচ | J76: =SUMIF($C$4:$C$203,$I76,$E$4:$E$203) | K76: =IFERROR($J76/$J$12,0)
D77: {=IFERROR(INDEX(GroupLookup,MATCH(C77,CategoryList,0)),"")} | I77: সর্বমোট | J77: =SUM($J$23:$J$76) | K77: =IFERROR($J$77/$J$12,0)
D78: {=IFERROR(INDEX(GroupLookup,MATCH(C78,CategoryList,0)),"")}
D79: {=IFERROR(INDEX(GroupLookup,MATCH(C79,CategoryList,0)),"")}
D80: {=IFERROR(INDEX(GroupLookup,MATCH(C80,CategoryList,0)),"")}
D81: {=IFERROR(INDEX(GroupLookup,MATCH(C81,CategoryList,0)),"")}
...

Sheet এপ্রিল ২০২৬
A1: দৈনিক খরচের হিসাব — এপ্রিল ২০২৬ | I1: মাসিক সারসংক্ষেপ
A2: শুধু তারিখ · বিবরণ · খাত · পরিমাণ · পেমেন্ট মাধ্যম · মন্তব্য ঘরগুলো পূরণ করুন। ‘গ্রুপ’ কলাম স্বয়ংক্রিয়ভাবে পূরণ হবে।
A3: তারিখ | B3: বিবরণ | C3: খাত | D3: গ্রুপ | E3: পরিমাণ (৳) | F3: পেমেন্ট মাধ্যম | G3: মন্তব্য | I3: গ্রুপ (প্রধান খাত) | J3: মোট (৳) | K3: শতাংশ
D4: {=IFERROR(INDEX(GroupLookup,MATCH(C4,CategoryList,0)),"")} | I4: খাদ্য ও মুদি | J4: =SUMIF($D$4:$D$203,$I4,$E$4:$E$203) | K4: =IFERROR($J4/$J$12,0)
D5: {=IFERROR(INDEX(GroupLookup,MATCH(C5,CategoryList,0)),"")} | I5: বাসস্থান | J5: =SUMIF($D$4:$D$203,$I5,$E$4:$E$203) | K5: =IFERROR($J5/$J$12,0)
D6: {=IFERROR(INDEX(GroupLookup,MATCH(C6,CategoryList,0)),"")} | I6: ইউটিলিটি বিল | J6: =SUMIF($D$4:$D$203,$I6,$E$4:$E$203) | K6: =IFERROR($J6/$J$12,0)
D7: {=IFERROR(INDEX(GroupLookup,MATCH(C7,CategoryList,0)),"")} | I7: যাতায়াত | J7: =SUMIF($D$4:$D$203,$I7,$E$4:$E$203) | K7: =IFERROR($J7/$J$12,0)
D8: {=IFERROR(INDEX(GroupLookup,MATCH(C8,CategoryList,0)),"")} | I8: স্বাস্থ্য | J8: =SUMIF($D$4:$D$203,$I8,$E$4:$E$203) | K8: =IFERROR($J8/$J$12,0)
D9: {=IFERROR(INDEX(GroupLookup,MATCH(C9,CategoryList,0)),"")} | I9: শিক্ষা | J9: =SUMIF($D$4:$D$203,$I9,$E$4:$E$203) | K9: =IFERROR($J9/$J$12,0)
D10: {=IFERROR(INDEX(GroupLookup,MATCH(C10,CategoryList,0)),"")} | I10: ব্যক্তিগত ও গৃহস্থালি | J10: =SUMIF($D$4:$D$203,$I10,$E$4:$E$203) | K10: =IFERROR($J10/$J$12,0)
D11: {=IFERROR(INDEX(GroupLookup,MATCH(C11,CategoryList,0)),"")} | I11: অন্যান্য | J11: =SUMIF($D$4:$D$203,$I11,$E$4:$E$203) | K11: =IFERROR($J11/$J$12,0)
D12: {=IFERROR(INDEX(GroupLookup,MATCH(C12,CategoryList,0)),"")} | I12: মোট মাসিক ব্যয় | J12: =SUM($E$4:$E$203) | K12: =IFERROR($J$12/$J$12,0)
D13: {=IFERROR(INDEX(GroupLookup,MATCH(C13,CategoryList,0)),"")} | I13: শ্রেণিবিন্যাসহীন (খাত তালিকায় নেই) | J13: =$J$12-SUM($J$4:$J$11) | K13: =IFERROR($J13/$J$12,0)
D14: {=IFERROR(INDEX(GroupLookup,MATCH(C14,CategoryList,0)),"")} | I14: গুরুত্বপূর্ণ তথ্য
D15: {=IFERROR(INDEX(GroupLookup,MATCH(C15,CategoryList,0)),"")} | I15: মোট লেনদেন সংখ্যা | J15: =COUNT($E$4:$E$203)
D16: {=IFERROR(INDEX(GroupLookup,MATCH(C16,CategoryList,0)),"")} | I16: দৈনিক গড় খরচ | J16: =IFERROR($J$12/30,0)
D17: {=IFERROR(INDEX(GroupLookup,MATCH(C17,CategoryList,0)),"")} | I17: প্রতি লেনদেনে গড় | J17: =IFERROR($J$12/COUNT($E$4:$E$203),0)
D18: {=IFERROR(INDEX(GroupLookup,MATCH(C18,CategoryList,0)),"")} | I18: সর্বোচ্চ একক খরচ | J18: =IFERROR(MAX($E$4:$E$203),0)
D19: {=IFERROR(INDEX(GroupLookup,MATCH(C19,CategoryList,0)),"")} | I19: সর্বোচ্চ ব্যয়ের গ্রুপ | J19: {=IF($J$12=0,"–",IFERROR(INDEX($I$4:$I$11,MATCH(MAX($J$4:$J$11),$J$4:$J$11,0)),"–"))}
D20: {=IFERROR(INDEX(GroupLookup,MATCH(C20,CategoryList,0)),"")} | I20: সর্বোচ্চ ব্যয়ের খাত | J20: {=IF($J$12=0,"–",IFERROR(INDEX($I$23:$I$76,MATCH(MAX($J$23:$J$76),$J$23:$J$76,0)),"–"))}
D21: {=IFERROR(INDEX(GroupLookup,MATCH(C21,CategoryList,0)),"")} | I21: খাতভিত্তিক বিস্তারিত
D22: {=IFERROR(INDEX(GroupLookup,MATCH(C22,CategoryList,0)),"")} | I22: খাত | J22: মোট (৳) | K22: শতাংশ
D23: {=IFERROR(INDEX(GroupLookup,MATCH(C23,CategoryList,0)),"")} | I23: চাল | J23: =SUMIF($C$4:$C$203,$I23,$E$4:$E$203) | K23: =IFERROR($J23/$J$12,0)
D24: {=IFERROR(INDEX(GroupLookup,MATCH(C24,CategoryList,0)),"")} | I24: আটা ও ময়দা | J24: =SUMIF($C$4:$C$203,$I24,$E$4:$E$203) | K24: =IFERROR($J24/$J$12,0)
D25: {=IFERROR(INDEX(GroupLookup,MATCH(C25,CategoryList,0)),"")} | I25: ডাল | J25: =SUMIF($C$4:$C$203,$I25,$E$4:$E$203) | K25: =IFERROR($J25/$J$12,0)
D26: {=IFERROR(INDEX(GroupLookup,MATCH(C26,CategoryList,0)),"")} | I26: মাছ | J26: =SUMIF($C$4:$C$203,$I26,$E$4:$E$203) | K26: =IFERROR($J26/$J$12,0)
D27: {=IFERROR(INDEX(GroupLookup,MATCH(C27,CategoryList,0)),"")} | I27: মাংস | J27: =SUMIF($C$4:$C$203,$I27,$E$4:$E$203) | K27: =IFERROR($J27/$J$12,0)
D28: {=IFERROR(INDEX(GroupLookup,MATCH(C28,CategoryList,0)),"")} | I28: ডিম | J28: =SUMIF($C$4:$C$203,$I28,$E$4:$E$203) | K28: =IFERROR($J28/$J$12,0)
D29: {=IFERROR(INDEX(GroupLookup,MATCH(C29,CategoryList,0)),"")} | I29: দুধ ও দুগ্ধজাত পণ্য | J29: =SUMIF($C$4:$C$203,$I29,$E$4:$E$203) | K29: =IFERROR($J29/$J$12,0)
D30: {=IFERROR(INDEX(GroupLookup,MATCH(C30,CategoryList,0)),"")} | I30: ভোজ্য তেল | J30: =SUMIF($C$4:$C$203,$I30,$E$4:$E$203) | K30: =IFERROR($J30/$J$12,0)
D31: {=IFERROR(INDEX(GroupLookup,MATCH(C31,CategoryList,0)),"")} | I31: শাক-সবজি | J31: =SUMIF($C$4:$C$203,$I31,$E$4:$E$203) | K31: =IFERROR($J31/$J$12,0)
D32: {=IFERROR(INDEX(GroupLookup,MATCH(C32,CategoryList,0)),"")} | I32: ফলমূল | J32: =SUMIF($C$4:$C$203,$I32,$E$4:$E$203) | K32: =IFERROR($J32/$J$12,0)
D33: {=IFERROR(INDEX(GroupLookup,MATCH(C33,CategoryList,0)),"")} | I33: মসলা | J33: =SUMIF($C$4:$C$203,$I33,$E$4:$E$203) | K33: =IFERROR($J33/$J$12,0)
D34: {=IFERROR(INDEX(GroupLookup,MATCH(C34,CategoryList,0)),"")} | I34: চিনি ও লবণ | J34: =SUMIF($C$4:$C$203,$I34,$E$4:$E$203) | K34: =IFERROR($J34/$J$12,0)
... D76: {=IFERROR(INDEX(GroupLookup,MATCH(C76,CategoryList,0)),"")} | I76: অন্যান্য খরচ | J76: =SUMIF($C$4:$C$203,$I76,$E$4:$E$203) | K76: =IFERROR($J76/$J$12,0)
D77: {=IFERROR(INDEX(GroupLookup,MATCH(C77,CategoryList,0)),"")} | I77: সর্বমোট | J77: =SUM($J$23:$J$76) | K77: =IFERROR($J$77/$J$12,0)
D78: {=IFERROR(INDEX(GroupLookup,MATCH(C78,CategoryList,0)),"")}
D79: {=IFERROR(INDEX(GroupLookup,MATCH(C79,CategoryList,0)),"")}
D80: {=IFERROR(INDEX(GroupLookup,MATCH(C80,CategoryList,0)),"")}
D81: {=IFERROR(INDEX(GroupLookup,MATCH(C81,CategoryList,0)),"")}
...

Sheet মে ২০২৬
A1: দৈনিক খরচের হিসাব — মে ২০২৬ | I1: মাসিক সারসংক্ষেপ
A2: শুধু তারিখ · বিবরণ · খাত · পরিমাণ · পেমেন্ট মাধ্যম · মন্তব্য ঘরগুলো পূরণ করুন। ‘গ্রুপ’ কলাম স্বয়ংক্রিয়ভাবে পূরণ হবে।
A3: তারিখ | B3: বিবরণ | C3: খাত | D3: গ্রুপ | E3: পরিমাণ (৳) | F3: পেমেন্ট মাধ্যম | G3: মন্তব্য | I3: গ্রুপ (প্রধান খাত) | J3: মোট (৳) | K3: শতাংশ
D4: {=IFERROR(INDEX(GroupLookup,MATCH(C4,CategoryList,0)),"")} | I4: খাদ্য ও মুদি | J4: =SUMIF($D$4:$D$203,$I4,$E$4:$E$203) | K4: =IFERROR($J4/$J$12,0)
D5: {=IFERROR(INDEX(GroupLookup,MATCH(C5,CategoryList,0)),"")} | I5: বাসস্থান | J5: =SUMIF($D$4:$D$203,$I5,$E$4:$E$203) | K5: =IFERROR($J5/$J$12,0)
D6: {=IFERROR(INDEX(GroupLookup,MATCH(C6,CategoryList,0)),"")} | I6: ইউটিলিটি বিল | J6: =SUMIF($D$4:$D$203,$I6,$E$4:$E$203) | K6: =IFERROR($J6/$J$12,0)
D7: {=IFERROR(INDEX(GroupLookup,MATCH(C7,CategoryList,0)),"")} | I7: যাতায়াত | J7: =SUMIF($D$4:$D$203,$I7,$E$4:$E$203) | K7: =IFERROR($J7/$J$12,0)
D8: {=IFERROR(INDEX(GroupLookup,MATCH(C8,CategoryList,0)),"")} | I8: স্বাস্থ্য | J8: =SUMIF($D$4:$D$203,$I8,$E$4:$E$203) | K8: =IFERROR($J8/$J$12,0)
D9: {=IFERROR(INDEX(GroupLookup,MATCH(C9,CategoryList,0)),"")} | I9: শিক্ষা | J9: =SUMIF($D$4:$D$203,$I9,$E$4:$E$203) | K9: =IFERROR($J9/$J$12,0)
D10: {=IFERROR(INDEX(GroupLookup,MATCH(C10,CategoryList,0)),"")} | I10: ব্যক্তিগত ও গৃহস্থালি | J10: =SUMIF($D$4:$D$203,$I10,$E$4:$E$203) | K10: =IFERROR($J10/$J$12,0)
D11: {=IFERROR(INDEX(GroupLookup,MATCH(C11,CategoryList,0)),"")} | I11: অন্যান্য | J11: =SUMIF($D$4:$D$203,$I11,$E$4:$E$203) | K11: =IFERROR($J11/$J$12,0)
D12: {=IFERROR(INDEX(GroupLookup,MATCH(C12,CategoryList,0)),"")} | I12: মোট মাসিক ব্যয় | J12: =SUM($E$4:$E$203) | K12: =IFERROR($J$12/$J$12,0)
D13: {=IFERROR(INDEX(GroupLookup,MATCH(C13,CategoryList,0)),"")} | I13: শ্রেণিবিন্যাসহীন (খাত তালিকায় নেই) | J13: =$J$12-SUM($J$4:$J$11) | K13: =IFERROR($J13/$J$12,0)
D14: {=IFERROR(INDEX(GroupLookup,MATCH(C14,CategoryList,0)),"")} | I14: গুরুত্বপূর্ণ তথ্য
D15: {=IFERROR(INDEX(GroupLookup,MATCH(C15,CategoryList,0)),"")} | I15: মোট লেনদেন সংখ্যা | J15: =COUNT($E$4:$E$203)
D16: {=IFERROR(INDEX(GroupLookup,MATCH(C16,CategoryList,0)),"")} | I16: দৈনিক গড় খরচ | J16: =IFERROR($J$12/31,0)
D17: {=IFERROR(INDEX(GroupLookup,MATCH(C17,CategoryList,0)),"")} | I17: প্রতি লেনদেনে গড় | J17: =IFERROR($J$12/COUNT($E$4:$E$203),0)
D18: {=IFERROR(INDEX(GroupLookup,MATCH(C18,CategoryList,0)),"")} | I18: সর্বোচ্চ একক খরচ | J18: =IFERROR(MAX($E$4:$E$203),0)
D19: {=IFERROR(INDEX(GroupLookup,MATCH(C19,CategoryList,0)),"")} | I19: সর্বোচ্চ ব্যয়ের গ্রুপ | J19: {=IF($J$12=0,"–",IFERROR(INDEX($I$4:$I$11,MATCH(MAX($J$4:$J$11),$J$4:$J$11,0)),"–"))}
D20: {=IFERROR(INDEX(GroupLookup,MATCH(C20,CategoryList,0)),"")} | I20: সর্বোচ্চ ব্যয়ের খাত | J20: {=IF($J$12=0,"–",IFERROR(INDEX($I$23:$I$76,MATCH(MAX($J$23:$J$76),$J$23:$J$76,0)),"–"))}
D21: {=IFERROR(INDEX(GroupLookup,MATCH(C21,CategoryList,0)),"")} | I21: খাতভিত্তিক বিস্তারিত
D22: {=IFERROR(INDEX(GroupLookup,MATCH(C22,CategoryList,0)),"")} | I22: খাত | J22: মোট (৳) | K22: শতাংশ
D23: {=IFERROR(INDEX(GroupLookup,MATCH(C23,CategoryList,0)),"")} | I23: চাল | J23: =SUMIF($C$4:$C$203,$I23,$E$4:$E$203) | K23: =IFERROR($J23/$J$12,0)
D24: {=IFERROR(INDEX(GroupLookup,MATCH(C24,CategoryList,0)),"")} | I24: আটা ও ময়দা | J24: =SUMIF($C$4:$C$203,$I24,$E$4:$E$203) | K24: =IFERROR($J24/$J$12,0)
D25: {=IFERROR(INDEX(GroupLookup,MATCH(C25,CategoryList,0)),"")} | I25: ডাল | J25: =SUMIF($C$4:$C$203,$I25,$E$4:$E$203) | K25: =IFERROR($J25/$J$12,0)
D26: {=IFERROR(INDEX(GroupLookup,MATCH(C26,CategoryList,0)),"")} | I26: মাছ | J26: =SUMIF($C$4:$C$203,$I26,$E$4:$E$203) | K26: =IFERROR($J26/$J$12,0)
D27: {=IFERROR(INDEX(GroupLookup,MATCH(C27,CategoryList,0)),"")} | I27: মাংস | J27: =SUMIF($C$4:$C$203,$I27,$E$4:$E$203) | K27: =IFERROR($J27/$J$12,0)
D28: {=IFERROR(INDEX(GroupLookup,MATCH(C28,CategoryList,0)),"")} | I28: ডিম | J28: =SUMIF($C$4:$C$203,$I28,$E$4:$E$203) | K28: =IFERROR($J28/$J$12,0)
D29: {=IFERROR(INDEX(GroupLookup,MATCH(C29,CategoryList,0)),"")} | I29: দুধ ও দুগ্ধজাত পণ্য | J29: =SUMIF($C$4:$C$203,$I29,$E$4:$E$203) | K29: =IFERROR($J29/$J$12,0)
D30: {=IFERROR(INDEX(GroupLookup,MATCH(C30,CategoryList,0)),"")} | I30: ভোজ্য তেল | J30: =SUMIF($C$4:$C$203,$I30,$E$4:$E$203) | K30: =IFERROR($J30/$J$12,0)
D31: {=IFERROR(INDEX(GroupLookup,MATCH(C31,CategoryList,0)),"")} | I31: শাক-সবজি | J31: =SUMIF($C$4:$C$203,$I31,$E$4:$E$203) | K31: =IFERROR($J31/$J$12,0)
D32: {=IFERROR(INDEX(GroupLookup,MATCH(C32,CategoryList,0)),"")} | I32: ফলমূল | J32: =SUMIF($C$4:$C$203,$I32,$E$4:$E$203) | K32: =IFERROR($J32/$J$12,0)
D33: {=IFERROR(INDEX(GroupLookup,MATCH(C33,CategoryList,0)),"")} | I33: মসলা | J33: =SUMIF($C$4:$C$203,$I33,$E$4:$E$203) | K33: =IFERROR($J33/$J$12,0)
D34: {=IFERROR(INDEX(GroupLookup,MATCH(C34,CategoryList,0)),"")} | I34: চিনি ও লবণ | J34: =SUMIF($C$4:$C$203,$I34,$E$4:$E$203) | K34: =IFERROR($J34/$J$12,0)
... D76: {=IFERROR(INDEX(GroupLookup,MATCH(C76,CategoryList,0)),"")} | I76: অন্যান্য খরচ | J76: =SUMIF($C$4:$C$203,$I76,$E$4:$E$203) | K76: =IFERROR($J76/$J$12,0)
D77: {=IFERROR(INDEX(GroupLookup,MATCH(C77,CategoryList,0)),"")} | I77: সর্বমোট | J77: =SUM($J$23:$J$76) | K77: =IFERROR($J$77/$J$12,0)
D78: {=IFERROR(INDEX(GroupLookup,MATCH(C78,CategoryList,0)),"")}
D79: {=IFERROR(INDEX(GroupLookup,MATCH(C79,CategoryList,0)),"")}
D80: {=IFERROR(INDEX(GroupLookup,MATCH(C80,CategoryList,0)),"")}
D81: {=IFERROR(INDEX(GroupLookup,MATCH(C81,CategoryList,0)),"")}
...

Sheet জুন ২০২৬
A1: দৈনিক খরচের হিসাব — জুন ২০২৬ | I1: মাসিক সারসংক্ষেপ
A2: শুধু তারিখ · বিবরণ · খাত · পরিমাণ · পেমেন্ট মাধ্যম · মন্তব্য ঘরগুলো পূরণ করুন। ‘গ্রুপ’ কলাম স্বয়ংক্রিয়ভাবে পূরণ হবে।
A3: তারিখ | B3: বিবরণ | C3: খাত | D3: গ্রুপ | E3: পরিমাণ (৳) | F3: পেমেন্ট মাধ্যম | G3: মন্তব্য | I3: গ্রুপ (প্রধান খাত) | J3: মোট (৳) | K3: শতাংশ
D4: {=IFERROR(INDEX(GroupLookup,MATCH(C4,CategoryList,0)),"")} | I4: খাদ্য ও মুদি | J4: =SUMIF($D$4:$D$203,$I4,$E$4:$E$203) | K4: =IFERROR($J4/$J$12,0)
D5: {=IFERROR(INDEX(GroupLookup,MATCH(C5,CategoryList,0)),"")} | I5: বাসস্থান | J5: =SUMIF($D$4:$D$203,$I5,$E$4:$E$203) | K5: =IFERROR($J5/$J$12,0)
D6: {=IFERROR(INDEX(GroupLookup,MATCH(C6,CategoryList,0)),"")} | I6: ইউটিলিটি বিল | J6: =SUMIF($D$4:$D$203,$I6,$E$4:$E$203) | K6: =IFERROR($J6/$J$12,0)
D7: {=IFERROR(INDEX(GroupLookup,MATCH(C7,CategoryList,0)),"")} | I7: যাতায়াত | J7: =SUMIF($D$4:$D$203,$I7,$E$4:$E$203) | K7: =IFERROR($J7/$J$12,0)
D8: {=IFERROR(INDEX(GroupLookup,MATCH(C8,CategoryList,0)),"")} | I8: স্বাস্থ্য | J8: =SUMIF($D$4:$D$203,$I8,$E$4:$E$203) | K8: =IFERROR($J8/$J$12,0)
D9: {=IFERROR(INDEX(GroupLookup,MATCH(C9,CategoryList,0)),"")} | I9: শিক্ষা | J9: =SUMIF($D$4:$D$203,$I9,$E$4:$E$203) | K9: =IFERROR($J9/$J$12,0)
D10: {=IFERROR(INDEX(GroupLookup,MATCH(C10,CategoryList,0)),"")} | I10: ব্যক্তিগত ও গৃহস্থালি | J10: =SUMIF($D$4:$D$203,$I10,$E$4:$E$203) | K10: =IFERROR($J10/$J$12,0)
D11: {=IFERROR(INDEX(GroupLookup,MATCH(C11,CategoryList,0)),"")} | I11: অন্যান্য | J11: =SUMIF($D$4:$D$203,$I11,$E$4:$E$203) | K11: =IFERROR($J11/$J$12,0)
D12: {=IFERROR(INDEX(GroupLookup,MATCH(C12,CategoryList,0)),"")} | I12: মোট মাসিক ব্যয় | J12: =SUM($E$4:$E$203) | K12: =IFERROR($J$12/$J$12,0)
D13: {=IFERROR(INDEX(GroupLookup,MATCH(C13,CategoryList,0)),"")} | I13: শ্রেণিবিন্যাসহীন (খাত তালিকায় নেই) | J13: =$J$12-SUM($J$4:$J$11) | K13: =IFERROR($J13/$J$12,0)
D14: {=IFERROR(INDEX(GroupLookup,MATCH(C14,CategoryList,0)),"")} | I14: গুরুত্বপূর্ণ তথ্য
D15: {=IFERROR(INDEX(GroupLookup,MATCH(C15,CategoryList,0)),"")} | I15: মোট লেনদেন সংখ্যা | J15: =COUNT($E$4:$E$203)
D16: {=IFERROR(INDEX(GroupLookup,MATCH(C16,CategoryList,0)),"")} | I16: দৈনিক গড় খরচ | J16: =IFERROR($J$12/30,0)
D17: {=IFERROR(INDEX(GroupLookup,MATCH(C17,CategoryList,0)),"")} | I17: প্রতি লেনদেনে গড় | J17: =IFERROR($J$12/COUNT($E$4:$E$203),0)
D18: {=IFERROR(INDEX(GroupLookup,MATCH(C18,CategoryList,0)),"")} | I18: সর্বোচ্চ একক খরচ | J18: =IFERROR(MAX($E$4:$E$203),0)
D19: {=IFERROR(INDEX(GroupLookup,MATCH(C19,CategoryList,0)),"")} | I19: সর্বোচ্চ ব্যয়ের গ্রুপ | J19: {=IF($J$12=0,"–",IFERROR(INDEX($I$4:$I$11,MATCH(MAX($J$4:$J$11),$J$4:$J$11,0)),"–"))}
D20: {=IFERROR(INDEX(GroupLookup,MATCH(C20,CategoryList,0)),"")} | I20: সর্বোচ্চ ব্যয়ের খাত | J20: {=IF($J$12=0,"–",IFERROR(INDEX($I$23:$I$76,MATCH(MAX($J$23:$J$76),$J$23:$J$76,0)),"–"))}
D21: {=IFERROR(INDEX(GroupLookup,MATCH(C21,CategoryList,0)),"")} | I21: খাতভিত্তিক বিস্তারিত
D22: {=IFERROR(INDEX(GroupLookup,MATCH(C22,CategoryList,0)),"")} | I22: খাত | J22: মোট (৳) | K22: শতাংশ
D23: {=IFERROR(INDEX(GroupLookup,MATCH(C23,CategoryList,0)),"")} | I23: চাল | J23: =SUMIF($C$4:$C$203,$I23,$E$4:$E$203) | K23: =IFERROR($J23/$J$12,0)
D24: {=IFERROR(INDEX(GroupLookup,MATCH(C24,CategoryList,0)),"")} | I24: আটা ও ময়দা | J24: =SUMIF($C$4:$C$203,$I24,$E$4:$E$203) | K24: =IFERROR($J24/$J$12,0)
D25: {=IFERROR(INDEX(GroupLookup,MATCH(C25,CategoryList,0)),"")} | I25: ডাল | J25: =SUMIF($C$4:$C$203,$I25,$E$4:$E$203) | K25: =IFERROR($J25/$J$12,0)
D26: {=IFERROR(INDEX(GroupLookup,MATCH(C26,CategoryList,0)),"")} | I26: মাছ | J26: =SUMIF($C$4:$C$203,$I26,$E$4:$E$203) | K26: =IFERROR($J26/$J$12,0)
D27: {=IFERROR(INDEX(GroupLookup,MATCH(C27,CategoryList,0)),"")} | I27: মাংস | J27: =SUMIF($C$4:$C$203,$I27,$E$4:$E$203) | K27: =IFERROR($J27/$J$12,0)
D28: {=IFERROR(INDEX(GroupLookup,MATCH(C28,CategoryList,0)),"")} | I28: ডিম | J28: =SUMIF($C$4:$C$203,$I28,$E$4:$E$203) | K28: =IFERROR($J28/$J$12,0)
D29: {=IFERROR(INDEX(GroupLookup,MATCH(C29,CategoryList,0)),"")} | I29: দুধ ও দুগ্ধজাত পণ্য | J29: =SUMIF($C$4:$C$203,$I29,$E$4:$E$203) | K29: =IFERROR($J29/$J$12,0)
D30: {=IFERROR(INDEX(GroupLookup,MATCH(C30,CategoryList,0)),"")} | I30: ভোজ্য তেল | J30: =SUMIF($C$4:$C$203,$I30,$E$4:$E$203) | K30: =IFERROR($J30/$J$12,0)
D31: {=IFERROR(INDEX(GroupLookup,MATCH(C31,CategoryList,0)),"")} | I31: শাক-সবজি | J31: =SUMIF($C$4:$C$203,$I31,$E$4:$E$203) | K31: =IFERROR($J31/$J$12,0)
D32: {=IFERROR(INDEX(GroupLookup,MATCH(C32,CategoryList,0)),"")} | I32: ফলমূল | J32: =SUMIF($C$4:$C$203,$I32,$E$4:$E$203) | K32: =IFERROR($J32/$J$12,0)
D33: {=IFERROR(INDEX(GroupLookup,MATCH(C33,CategoryList,0)),"")} | I33: মসলা | J33: =SUMIF($C$4:$C$203,$I33,$E$4:$E$203) | K33: =IFERROR($J33/$J$12,0)
D34: {=IFERROR(INDEX(GroupLookup,MATCH(C34,CategoryList,0)),"")} | I34: চিনি ও লবণ | J34: =SUMIF($C$4:$C$203,$I34,$E$4:$E$203) | K34: =IFERROR($J34/$J$12,0)
... D76: {=IFERROR(INDEX(GroupLookup,MATCH(C76,CategoryList,0)),"")} | I76: অন্যান্য খরচ | J76: =SUMIF($C$4:$C$203,$I76,$E$4:$E$203) | K76: =IFERROR($J76/$J$12,0)
D77: {=IFERROR(INDEX(GroupLookup,MATCH(C77,CategoryList,0)),"")} | I77: সর্বমোট | J77: =SUM($J$23:$J$76) | K77: =IFERROR($J$77/$J$12,0)
D78: {=IFERROR(INDEX(GroupLookup,MATCH(C78,CategoryList,0)),"")}
D79: {=IFERROR(INDEX(GroupLookup,MATCH(C79,CategoryList,0)),"")}
D80: {=IFERROR(INDEX(GroupLookup,MATCH(C80,CategoryList,0)),"")}
D81: {=IFERROR(INDEX(GroupLookup,MATCH(C81,CategoryList,0)),"")}
...

Sheet জুলাই ২০২৬
A1: দৈনিক খরচের হিসাব — জুলাই ২০২৬ | I1: মাসিক সারসংক্ষেপ
